<?xml version="1.0" ?>
<!-- =================================================================================== -->
<!-- |    This document was autogenerated by xacro from limbarm_robot.xacro            | -->
<!-- |    EDITING THIS FILE BY HAND IS NOT RECOMMENDED                                 | -->
<!-- =================================================================================== -->
<!-- This URDF was automatically created by SolidWorks to URDF Exporter! Originally created by Stephen Brawner (brawner@gmail.com) 
     Commit Version: 1.6.0-1-g15f4949  Build Version: 1.6.7594.29634
     For more information, please see http://wiki.ros.org/sw_urdf_exporter -->
<robot name="limbarm_robot">
  <!--body*********************************************************************************************************-->
  <!-- Define the dummy link -->
  <link name="dummy_link">
    <!-- No inertial element is necessary for the dummy link -->
  </link>
  <link name="base_link">
    <inertial>
      <origin xyz="0 0 0" rpy="0 0 0"/>
      <mass value="0.207227651472846"/>
      <inertia ixx="0.000864776609063061" ixy="1.70761842166467E-18" ixz="-3.90064549015996E-19" iyy="0.000864776609063067" iyz="-7.32576739205599E-20" izz="0.00169698819383654"/>
    </inertial>
    <visual>
      <origin xyz="0 0 0" rpy="0 0 0"/>
      <geometry>
        <mesh filename="package://limbarm-robot/meshes/base_link.STL"/>
      </geometry>
      <material name="">
        <color rgba="0.898039215686275 0.917647058823529 0.929411764705882 1"/>
      </material>
    </visual>
    <collision>
      <origin xyz="0 0 0" rpy="0 0 0"/>
      <geometry>
        <mesh filename="package://limbarm-robot/meshes/base_link.STL"/>
      </geometry>
    </collision>
  </link>
  <!-- Define a fixed joint between the dummy link and the base_link -->
  <joint name="dummy_joint" type="fixed">
    <parent link="dummy_link"/>
    <child link="base_link"/>
    <origin xyz="0 0 0.55" rpy="-1.5708 0 0"/>
  </joint>
  <!-- <link name="Link_platform">
    <inertial>
      <origin rpy="0 0 0" xyz="8.3809632400694E-17 -3.87522401236673E-16 0.0118908439474308"/>
      <mass value="0.2130133080088"/>
      <inertia ixx="0.000750053187775699" ixy="-2.71050543121376E-20" ixz="-1.56668488086988E-19" iyy="0.000750053187775698" iyz="-1.32295904238123E-17" izz="0.00145982770981803"/>
    </inertial>
    <visual>
      <origin rpy="0 0 0" xyz="0 0 0"/>
      <geometry>
        <mesh filename="package://limbarm-robot/meshes/Link_platform.STL"/>
      </geometry>
      <material name="">
        <color rgba="0.898039215686275 0.917647058823529 0.929411764705882 1"/>
      </material>
    </visual>
    <collision>
      <origin rpy="0 0 0" xyz="0 0 0"/>
      <geometry>
        <mesh filename="package://limbarm-robot/meshes/Link_platform.STL"/>
      </geometry>
    </collision>
  </link>
  <joint name="Joint_platform" type="prismatic">
    <origin rpy="0 0 0" xyz="0 0 0.043397"/>
    <parent link="base_link"/>
    <child link="Link_platform"/>
    <axis xyz="0 0 1"/>
    <limit effort="0" lower="0" upper="0.2" velocity="0"/>
  </joint> -->
  <link name="Link1_0">
    <inertial>
      <origin rpy="0 0 0" xyz="0.0664169606230434 -0.0201281947592238 4.76216409223294E-09"/>
      <mass value="0.167855923175507"/>
      <inertia ixx="0.000138967813923233" ixy="0.00013034966620524" ixz="4.19274572448473E-10" iyy="0.000359258276622689" iyz="-4.93247675598086E-10" izz="0.00040872901975892"/>
    </inertial>
    <visual>
      <origin rpy="0 0 0" xyz="0 0 0"/>
      <geometry>
        <mesh filename="package://limbarm-robot/meshes/Link_0.STL"/>
      </geometry>
      <material name="">
        <color rgba="0.898039215686275 0.917647058823529 0.929411764705882 1"/>
      </material>
    </visual>
    <collision>
      <origin rpy="0 0 0" xyz="0 0 0"/>
      <geometry>
        <mesh filename="package://limbarm-robot/meshes/Link_0.STL"/>
      </geometry>
    </collision>
  </link>
  <joint name="Joint1_0" type="revolute">
    <origin rpy="1.5708 0 0.7854" xyz="0.072125 0.072125 0.018"/>
    <parent link="base_link"/>
    <child link="Link1_0"/>
    <axis xyz="0 0 1"/>
    <limit effort="0" lower="0" upper="1.5707963267948966" velocity="0"/>
  </joint>
  <link name="Link1_1">
    <inertial>
      <origin rpy="0 0 0" xyz="0.0250848566132372 0.00345843485933482 0.0514637195946037"/>
      <mass value="0.0924049155630686"/>
      <inertia ixx="0.000113655728960563" ixy="-5.80244611122902E-06" ixz="-3.76444889979073E-06" iyy="0.000108121821578899" iyz="-3.49900344610929E-10" izz="9.35026260489851E-05"/>
    </inertial>
    <visual>
      <origin rpy="0 0 0" xyz="0 0 0"/>
      <geometry>
        <mesh filename="package://limbarm-robot/meshes/Link_1.STL"/>
      </geometry>
      <material name="">
        <color rgba="1 1 1 1"/>
      </material>
    </visual>
    <collision>
      <origin rpy="0 0 0" xyz="0 0 0"/>
      <geometry>
        <mesh filename="package://limbarm-robot/meshes/Link_1.STL"/>
      </geometry>
    </collision>
  </link>
  <joint name="Joint1_1" type="revolute">
    <origin rpy="1.5708 0 0" xyz="0.12 -0.058 0"/>
    <parent link="Link1_0"/>
    <child link="Link1_1"/>
    <axis xyz="0 0 1"/>
    <limit effort="0" lower="-2.094395102393195" upper="2.094395102393195" velocity="0"/>
  </joint>
  <link name="Link1_2">
    <inertial>
      <origin rpy="0 0 0" xyz="0.164755159604738 5.52891938350869E-05 0.00408065381894232"/>
      <mass value="0.199013621726556"/>
      <inertia ixx="0.000157061185619374" ixy="1.12205157240906E-10" ixz="1.68248403114826E-05" iyy="0.000550518166051161" iyz="3.11728051125751E-11" izz="0.000520833679086167"/>
    </inertial>
    <visual>
      <origin rpy="0 0 0" xyz="0 0 0"/>
      <geometry>
        <mesh filename="package://limbarm-robot/meshes/Link_2.STL"/>
      </geometry>
      <material name="">
        <color rgba="1 1 1 1"/>
      </material>
    </visual>
    <collision>
      <origin rpy="0 0 0" xyz="0 0 0"/>
      <geometry>
        <mesh filename="package://limbarm-robot/meshes/Link_2.STL"/>
      </geometry>
    </collision>
  </link>
  <joint name="Joint1_2" type="revolute">
    <origin rpy="-1.5708 0 0" xyz="0.0625 0.0025 0.059"/>
    <parent link="Link1_1"/>
    <child link="Link1_2"/>
    <axis xyz="0 0 1"/>
    <limit effort="0" lower="-2.0943951023931953" upper="1.5707963267948966" velocity="0"/>
  </joint>
  <link name="Link1_3">
    <inertial>
      <origin rpy="0 0 0" xyz="0.0720097797375396 -0.000448350531068148 0.00124427030485257"/>
      <mass value="0.133696366167161"/>
      <inertia ixx="0.000115445322405323" ixy="-2.9390750086264E-07" ixz="3.41837661585693E-05" iyy="0.000205794166012378" iyz="-7.33953327793886E-11" izz="0.000182900509037997"/>
    </inertial>
    <visual>
      <origin rpy="0 0 0" xyz="0 0 0"/>
      <geometry>
        <mesh filename="package://limbarm-robot/meshes/Link_3.STL"/>
      </geometry>
      <material name="">
        <color rgba="1 1 1 1"/>
      </material>
    </visual>
    <collision>
      <origin rpy="0 0 0" xyz="0 0 0"/>
      <geometry>
        <mesh filename="package://limbarm-robot/meshes/Link_3.STL"/>
      </geometry>
    </collision>
  </link>
  <joint name="Joint1_3" type="revolute">
    <origin rpy="0 0 0" xyz="0.35 0.0002 0"/>
    <parent link="Link1_2"/>
    <child link="Link1_3"/>
    <axis xyz="0 0 1"/>
    <limit effort="0" lower="-2.530727415391778" upper="2.530727415391778" velocity="0"/>
  </joint>
  <link name="Link1_4">
    <inertial>
      <origin rpy="0 0 0" xyz="-0.00219595597659072 5.55111512312578E-17 0.10937323066911"/>
      <mass value="0.0991853302135674"/>
      <inertia ixx="0.000103997514125068" ixy="-1.20729995670382E-20" ixz="4.04878902852236E-06" iyy="0.000118364894914693" iyz="2.39343771466793E-20" izz="7.06314967499001E-05"/>
    </inertial>
    <visual>
      <origin rpy="0 0 0" xyz="0 0 0"/>
      <geometry>
        <mesh filename="package://limbarm-robot/meshes/Link_4.STL"/>
      </geometry>
      <material name="">
        <color rgba="1 1 1 1"/>
      </material>
    </visual>
    <collision>
      <origin rpy="0 0 0" xyz="0 0 0"/>
      <geometry>
        <mesh filename="package://limbarm-robot/meshes/Link_4.STL"/>
      </geometry>
    </collision>
  </link>
  <joint name="Joint1_4" type="revolute">
    <origin rpy="0 1.5708 0" xyz="0.1745 0 0"/>
    <parent link="Link1_3"/>
    <child link="Link1_4"/>
    <axis xyz="0 0 1"/>
    <limit effort="0" lower="-3.141592653589793" upper="3.141592653589793" velocity="0"/>
  </joint>
  <link name="Link1_5">
    <inertial>
      <origin rpy="0 0 0" xyz="0.0516421278227287 -0.000601786312485739 0.00160323320931993"/>
      <mass value="0.102911752371677"/>
      <inertia ixx="9.39942726273345E-05" ixy="-2.93181599029908E-07" ixz="1.73270940326199E-05" iyy="0.000113244406627227" iyz="-3.14838914806693E-10" izz="8.10585911724992E-05"/>
    </inertial>
    <visual>
      <origin rpy="0 0 0" xyz="0 0 0"/>
      <geometry>
        <mesh filename="package://limbarm-robot/meshes/Link_5.STL"/>
      </geometry>
      <material name="">
        <color rgba="1 1 1 1"/>
      </material>
    </visual>
    <collision>
      <origin rpy="0 0 0" xyz="0 0 0"/>
      <geometry>
        <mesh filename="package://limbarm-robot/meshes/Link_5.STL"/>
      </geometry>
    </collision>
  </link>
  <joint name="Joint1_5" type="revolute">
    <origin rpy="3.1416 -1.5708 0" xyz="0 0 0.1795"/>
    <parent link="Link1_4"/>
    <child link="Link1_5"/>
    <axis xyz="0 0 1"/>
    <limit effort="0" lower="-1.9198621771937623" upper="1.9198621771937623" velocity="0"/>
  </joint>
  <link name="Link1_6">
    <inertial>
      <origin rpy="0 0 0" xyz="0.000146447962600783 0.000132910316064216 0.0194222181514005"/>
      <mass value="0.134599349728801"/>
      <inertia ixx="5.54993019233277E-05" ixy="-3.42434491188341E-07" ixz="1.1735586211374E-07" iyy="5.54034726867672E-05" iyz="9.38344787747327E-08" izz="9.77383386331803E-05"/>
    </inertial>
    <visual>
      <origin rpy="0 0 0" xyz="0 0 0"/>
      <geometry>
        <mesh filename="package://limbarm-robot/meshes/Link_6.STL"/>
      </geometry>
      <material name="">
        <color rgba="1 1 1 1"/>
      </material>
    </visual>
    <collision>
      <origin rpy="0 0 0" xyz="0 0 0"/>
      <geometry>
        <mesh filename="package://limbarm-robot/meshes/Link_6.STL"/>
      </geometry>
    </collision>
  </link>
  <joint name="Joint1_6" type="revolute">
    <origin rpy="0 1.5708 0" xyz="0.141 0 0"/>
    <parent link="Link1_5"/>
    <child link="Link1_6"/>
    <axis xyz="0 0 1"/>
    <limit effort="0" lower="-3.141592653589793" upper="3.141592653589793" velocity="0"/>
  </joint>
  <link name="Link1_Hand">
      <inertial>
        <origin rpy="0 0 0" xyz="-5.34486019601772E-05 -0.00163292800302499 0.0718038327986019"/>
        <mass value="0.306213518195145" />
        <inertia ixx="0.000241886583337232" ixy="-7.53752414578879E-06" ixz="-4.09966232551133E-08" iyy="0.000127174038942717" iyz="1.77993490423381E-06" izz="0.000271550204634038" />
      </inertial>
      <visual>
        <origin rpy="0 0 0" xyz="0 0 0"/>
        <geometry>
          <mesh filename="package://limbarm-robot/meshes/Hand.STL" />
        </geometry>
        <material name="">
          <color rgba="1 1 1 1" />
        </material>
      </visual>
      <collision>
        <origin rpy="0 0 0" xyz="0 0 0"/>
        <geometry>
          <mesh
            filename="package://limbarm-robot/meshes/Hand.STL" />
        </geometry>
      </collision>
  </link>
  <joint name="Joint1_hand"
      type="fixed">
      <origin rpy="0 0 0" xyz="0 0 0.0385"/>
      <parent link="Link1_6" />
      <child link="Link1_Hand" />
      <axis xyz="0 0 0" />
  </joint>
  <link name="Link2_0">
      <inertial>
        <origin rpy="0 0 0" xyz="0.0664169606230434 -0.0201281947592238 4.76216409223294E-09"/>
        <mass value="0.167855923175507"/>
        <inertia ixx="0.000138967813923233" ixy="0.00013034966620524" ixz="4.19274572448473E-10" iyy="0.000359258276622689" iyz="-4.93247675598086E-10" izz="0.00040872901975892"/>
      </inertial>
      <visual>
        <origin rpy="0 0 0" xyz="0 0 0"/>
        <geometry>
          <mesh filename="package://limbarm-robot/meshes/Link_0.STL"/>
        </geometry>
        <material name="">
          <color rgba="0.898039215686275 0.917647058823529 0.929411764705882 1"/>
        </material>
      </visual>
      <collision>
        <origin rpy="0 0 0" xyz="0 0 0"/>
        <geometry>
          <mesh filename="package://limbarm-robot/meshes/Link_0.STL"/>
        </geometry>
      </collision>
  </link>
  <joint name="Joint2_0" type="revolute">
      <origin rpy="1.5708 0 2.3562" xyz="-0.072125 0.072125 0.018"/>
      <parent link="base_link"/>
      <child link="Link2_0"/>
      <axis xyz="0 0 1"/>
      <limit effort="0" lower="0" upper="1.5707963267948966" velocity="0"/>
  </joint>
  <link name="Link2_1">
      <inertial>
        <origin rpy="0 0 0" xyz="0.0250848566132372 0.00345843485933482 0.0514637195946037"/>
        <mass value="0.0924049155630686"/>
        <inertia ixx="0.000113655728960563" ixy="-5.80244611122902E-06" ixz="-3.76444889979073E-06" iyy="0.000108121821578899" iyz="-3.49900344610929E-10" izz="9.35026260489851E-05"/>
      </inertial>
      <visual>
        <origin rpy="0 0 0" xyz="0 0 0"/>
        <geometry>
          <mesh filename="package://limbarm-robot/meshes/Link_1.STL"/>
        </geometry>
        <material name="">
          <color rgba="1 1 1 1"/>
        </material>
      </visual>
      <collision>
        <origin rpy="0 0 0" xyz="0 0 0"/>
        <geometry>
          <mesh filename="package://limbarm-robot/meshes/Link_1.STL"/>
        </geometry>
      </collision>
  </link>
  <joint name="Joint2_1" type="revolute">
      <origin rpy="1.5708 0 0" xyz="0.12 -0.058 0"/>
      <parent link="Link2_0"/>
      <child link="Link2_1"/>
      <axis xyz="0 0 1"/>
      <limit effort="0" lower="-2.094395102393195" upper="2.094395102393195" velocity="0"/>
  </joint>
  <link name="Link2_2">
      <inertial>
        <origin rpy="0 0 0" xyz="0.164755159604738 5.52891938350869E-05 0.00408065381894232"/>
        <mass value="0.199013621726556"/>
        <inertia ixx="0.000157061185619374" ixy="1.12205157240906E-10" ixz="1.68248403114826E-05" iyy="0.000550518166051161" iyz="3.11728051125751E-11" izz="0.000520833679086167"/>
      </inertial>
      <visual>
        <origin rpy="0 0 0" xyz="0 0 0"/>
        <geometry>
          <mesh filename="package://limbarm-robot/meshes/Link_2.STL"/>
        </geometry>
        <material name="">
          <color rgba="1 1 1 1"/>
        </material>
      </visual>
      <collision>
        <origin rpy="0 0 0" xyz="0 0 0"/>
        <geometry>
          <mesh filename="package://limbarm-robot/meshes/Link_2.STL"/>
        </geometry>
      </collision>
  </link>
  <joint name="Joint2_2" type="revolute">
      <origin rpy="-1.5708 0 0" xyz="0.0625 0.0025 0.059"/>
      <parent link="Link2_1"/>
      <child link="Link2_2"/>
      <axis xyz="0 0 1"/>
      <limit effort="0" lower="-2.0943951023931953" upper="1.5707963267948966" velocity="0"/>
  </joint>
  <link name="Link2_3">
      <inertial>
        <origin rpy="0 0 0" xyz="0.0720097797375396 -0.000448350531068148 0.00124427030485257"/>
        <mass value="0.133696366167161"/>
        <inertia ixx="0.000115445322405323" ixy="-2.9390750086264E-07" ixz="3.41837661585693E-05" iyy="0.000205794166012378" iyz="-7.33953327793886E-11" izz="0.000182900509037997"/>
      </inertial>
      <visual>
        <origin rpy="0 0 0" xyz="0 0 0"/>
        <geometry>
          <mesh filename="package://limbarm-robot/meshes/Link_3.STL"/>
        </geometry>
        <material name="">
          <color rgba="1 1 1 1"/>
        </material>
      </visual>
      <collision>
        <origin rpy="0 0 0" xyz="0 0 0"/>
        <geometry>
          <mesh filename="package://limbarm-robot/meshes/Link_3.STL"/>
        </geometry>
      </collision>
  </link>
  <joint name="Joint2_3" type="revolute">
      <origin rpy="0 0 0" xyz="0.35 0.0002 0"/>
      <parent link="Link2_2"/>
      <child link="Link2_3"/>
      <axis xyz="0 0 1"/>
      <limit effort="0" lower="-2.530727415391778" upper="2.530727415391778" velocity="0"/>
  </joint>
  <link name="Link2_4">
      <inertial>
        <origin rpy="0 0 0" xyz="-0.00219595597659072 5.55111512312578E-17 0.10937323066911"/>
        <mass value="0.0991853302135674"/>
        <inertia ixx="0.000103997514125068" ixy="-1.20729995670382E-20" ixz="4.04878902852236E-06" iyy="0.000118364894914693" iyz="2.39343771466793E-20" izz="7.06314967499001E-05"/>
      </inertial>
      <visual>
        <origin rpy="0 0 0" xyz="0 0 0"/>
        <geometry>
          <mesh filename="package://limbarm-robot/meshes/Link_4.STL"/>
        </geometry>
        <material name="">
          <color rgba="1 1 1 1"/>
        </material>
      </visual>
      <collision>
        <origin rpy="0 0 0" xyz="0 0 0"/>
        <geometry>
          <mesh filename="package://limbarm-robot/meshes/Link_4.STL"/>
        </geometry>
      </collision>
  </link>
  <joint name="Joint2_4" type="revolute">
      <origin rpy="0 1.5708 0" xyz="0.1745 0 0"/>
      <parent link="Link2_3"/>
      <child link="Link2_4"/>
      <axis xyz="0 0 1"/>
      <limit effort="0" lower="-3.141592653589793" upper="3.141592653589793" velocity="0"/>
  </joint>
  <link name="Link2_5">
      <inertial>
        <origin rpy="0 0 0" xyz="0.0516421278227287 -0.000601786312485739 0.00160323320931993"/>
        <mass value="0.102911752371677"/>
        <inertia ixx="9.39942726273345E-05" ixy="-2.93181599029908E-07" ixz="1.73270940326199E-05" iyy="0.000113244406627227" iyz="-3.14838914806693E-10" izz="8.10585911724992E-05"/>
      </inertial>
      <visual>
        <origin rpy="0 0 0" xyz="0 0 0"/>
        <geometry>
          <mesh filename="package://limbarm-robot/meshes/Link_5.STL"/>
        </geometry>
        <material name="">
          <color rgba="1 1 1 1"/>
        </material>
      </visual>
      <collision>
        <origin rpy="0 0 0" xyz="0 0 0"/>
        <geometry>
          <mesh filename="package://limbarm-robot/meshes/Link_5.STL"/>
        </geometry>
      </collision>
  </link>
  <joint name="Joint2_5" type="revolute">
      <origin rpy="3.1416 -1.5708 0" xyz="0 0 0.1795"/>
      <parent link="Link2_4"/>
      <child link="Link2_5"/>
      <axis xyz="0 0 1"/>
      <limit effort="0" lower="-1.9198621771937623" upper="1.9198621771937623" velocity="0"/>
  </joint>
  <link name="Link2_6">
      <inertial>
        <origin rpy="0 0 0" xyz="0.000146447962600783 0.000132910316064216 0.0194222181514005"/>
        <mass value="0.134599349728801"/>
        <inertia ixx="5.54993019233277E-05" ixy="-3.42434491188341E-07" ixz="1.1735586211374E-07" iyy="5.54034726867672E-05" iyz="9.38344787747327E-08" izz="9.77383386331803E-05"/>
      </inertial>
      <visual>
        <origin rpy="0 0 0" xyz="0 0 0"/>
        <geometry>
          <mesh filename="package://limbarm-robot/meshes/Link_6.STL"/>
        </geometry>
        <material name="">
          <color rgba="1 1 1 1"/>
        </material>
      </visual>
      <collision>
        <origin rpy="0 0 0" xyz="0 0 0"/>
        <geometry>
          <mesh filename="package://limbarm-robot/meshes/Link_6.STL"/>
        </geometry>
      </collision>
  </link>
  <joint name="Joint2_6" type="revolute">
      <origin rpy="0 1.5708 0" xyz="0.141 0 0"/>
      <parent link="Link2_5"/>
      <child link="Link2_6"/>
      <axis xyz="0 0 1"/>
      <limit effort="0" lower="-3.141592653589793" upper="3.141592653589793" velocity="0"/>
  </joint>
  <link name="Link2_Hand">
      <inertial>
        <origin rpy="0 0 0" xyz="-5.34486019601772E-05 -0.00163292800302499 0.0718038327986019"/>
        <mass value="0.306213518195145" />
        <inertia ixx="0.000241886583337232" ixy="-7.53752414578879E-06" ixz="-4.09966232551133E-08" iyy="0.000127174038942717" iyz="1.77993490423381E-06" izz="0.000271550204634038" />
      </inertial>
      <visual>
        <origin rpy="0 0 0" xyz="0 0 0"/>
        <geometry>
          <mesh filename="package://limbarm-robot/meshes/Hand.STL" />
        </geometry>
        <material name="">
          <color rgba="1 1 1 1" />
        </material>
      </visual>
      <collision>
        <origin rpy="0 0 0" xyz="0 0 0"/>
        <geometry>
          <mesh
            filename="package://limbarm-robot/meshes/Hand.STL" />
        </geometry>
      </collision>
  </link>
  <joint name="Joint2_hand"
      type="fixed">
      <origin rpy="0 0 0" xyz="0 0 0.0385"/>
      <parent link="Link2_6" />
      <child link="Link2_Hand" />
      <axis xyz="0 0 0" />
  </joint>
  <link name="Link3_0">
      <inertial>
        <origin rpy="0 0 0" xyz="0.0664169606230434 -0.0201281947592238 4.76216409223294E-09"/>
        <mass value="0.167855923175507"/>
        <inertia ixx="0.000138967813923233" ixy="0.00013034966620524" ixz="4.19274572448473E-10" iyy="0.000359258276622689" iyz="-4.93247675598086E-10" izz="0.00040872901975892"/>
      </inertial>
      <visual>
        <origin rpy="0 0 0" xyz="0 0 0"/>
        <geometry>
          <mesh filename="package://limbarm-robot/meshes/Link_0.STL"/>
        </geometry>
        <material name="">
          <color rgba="0.898039215686275 0.917647058823529 0.929411764705882 1"/>
        </material>
      </visual>
      <collision>
        <origin rpy="0 0 0" xyz="0 0 0"/>
        <geometry>
          <mesh filename="package://limbarm-robot/meshes/Link_0.STL"/>
        </geometry>
      </collision>
  </link>
  <joint name="Joint3_0" type="revolute">
      <origin rpy="1.5708 0 -0.7854" xyz="0.072125 -0.072125 0.018"/>
      <parent link="base_link"/>
      <child link="Link3_0"/>
      <axis xyz="0 0 1"/>
      <limit effort="0" lower="0" upper="1.5707963267948966" velocity="0"/>
  </joint>
  <link name="Link3_1">
      <inertial>
        <origin rpy="0 0 0" xyz="0.0250848566132372 0.00345843485933482 0.0514637195946037"/>
        <mass value="0.0924049155630686"/>
        <inertia ixx="0.000113655728960563" ixy="-5.80244611122902E-06" ixz="-3.76444889979073E-06" iyy="0.000108121821578899" iyz="-3.49900344610929E-10" izz="9.35026260489851E-05"/>
      </inertial>
      <visual>
        <origin rpy="0 0 0" xyz="0 0 0"/>
        <geometry>
          <mesh filename="package://limbarm-robot/meshes/Link_1.STL"/>
        </geometry>
        <material name="">
          <color rgba="1 1 1 1"/>
        </material>
      </visual>
      <collision>
        <origin rpy="0 0 0" xyz="0 0 0"/>
        <geometry>
          <mesh filename="package://limbarm-robot/meshes/Link_1.STL"/>
        </geometry>
      </collision>
  </link>
  <joint name="Joint3_1" type="revolute">
      <origin rpy="1.5708 0 0" xyz="0.12 -0.058 0"/>
      <parent link="Link3_0"/>
      <child link="Link3_1"/>
      <axis xyz="0 0 1"/>
      <limit effort="0" lower="-2.094395102393195" upper="2.094395102393195" velocity="0"/>
  </joint>
  <link name="Link3_2">
      <inertial>
        <origin rpy="0 0 0" xyz="0.164755159604738 5.52891938350869E-05 0.00408065381894232"/>
        <mass value="0.199013621726556"/>
        <inertia ixx="0.000157061185619374" ixy="1.12205157240906E-10" ixz="1.68248403114826E-05" iyy="0.000550518166051161" iyz="3.11728051125751E-11" izz="0.000520833679086167"/>
      </inertial>
      <visual>
        <origin rpy="0 0 0" xyz="0 0 0"/>
        <geometry>
          <mesh filename="package://limbarm-robot/meshes/Link_2.STL"/>
        </geometry>
        <material name="">
          <color rgba="1 1 1 1"/>
        </material>
      </visual>
      <collision>
        <origin rpy="0 0 0" xyz="0 0 0"/>
        <geometry>
          <mesh filename="package://limbarm-robot/meshes/Link_2.STL"/>
        </geometry>
      </collision>
  </link>
  <joint name="Joint3_2" type="revolute">
      <origin rpy="-1.5708 0 0" xyz="0.0625 0.0025 0.059"/>
      <parent link="Link3_1"/>
      <child link="Link3_2"/>
      <axis xyz="0 0 1"/>
      <limit effort="0" lower="-2.0943951023931953" upper="1.5707963267948966" velocity="0"/>
  </joint>
  <link name="Link3_3">
      <inertial>
        <origin rpy="0 0 0" xyz="0.0720097797375396 -0.000448350531068148 0.00124427030485257"/>
        <mass value="0.133696366167161"/>
        <inertia ixx="0.000115445322405323" ixy="-2.9390750086264E-07" ixz="3.41837661585693E-05" iyy="0.000205794166012378" iyz="-7.33953327793886E-11" izz="0.000182900509037997"/>
      </inertial>
      <visual>
        <origin rpy="0 0 0" xyz="0 0 0"/>
        <geometry>
          <mesh filename="package://limbarm-robot/meshes/Link_3.STL"/>
        </geometry>
        <material name="">
          <color rgba="1 1 1 1"/>
        </material>
      </visual>
      <collision>
        <origin rpy="0 0 0" xyz="0 0 0"/>
        <geometry>
          <mesh filename="package://limbarm-robot/meshes/Link_3.STL"/>
        </geometry>
      </collision>
  </link>
  <joint name="Joint3_3" type="revolute">
      <origin rpy="0 0 0" xyz="0.35 0.0002 0"/>
      <parent link="Link3_2"/>
      <child link="Link3_3"/>
      <axis xyz="0 0 1"/>
      <limit effort="0" lower="-2.530727415391778" upper="2.530727415391778" velocity="0"/>
  </joint>
  <link name="Link3_4">
      <inertial>
        <origin rpy="0 0 0" xyz="-0.00219595597659072 5.55111512312578E-17 0.10937323066911"/>
        <mass value="0.0991853302135674"/>
        <inertia ixx="0.000103997514125068" ixy="-1.20729995670382E-20" ixz="4.04878902852236E-06" iyy="0.000118364894914693" iyz="2.39343771466793E-20" izz="7.06314967499001E-05"/>
      </inertial>
      <visual>
        <origin rpy="0 0 0" xyz="0 0 0"/>
        <geometry>
          <mesh filename="package://limbarm-robot/meshes/Link_4.STL"/>
        </geometry>
        <material name="">
          <color rgba="1 1 1 1"/>
        </material>
      </visual>
      <collision>
        <origin rpy="0 0 0" xyz="0 0 0"/>
        <geometry>
          <mesh filename="package://limbarm-robot/meshes/Link_4.STL"/>
        </geometry>
      </collision>
  </link>
  <joint name="Joint3_4" type="revolute">
      <origin rpy="0 1.5708 0" xyz="0.1745 0 0"/>
      <parent link="Link3_3"/>
      <child link="Link3_4"/>
      <axis xyz="0 0 1"/>
      <limit effort="0" lower="-3.141592653589793" upper="3.141592653589793" velocity="0"/>
  </joint>
  <link name="Link3_5">
      <inertial>
        <origin rpy="0 0 0" xyz="0.0516421278227287 -0.000601786312485739 0.00160323320931993"/>
        <mass value="0.102911752371677"/>
        <inertia ixx="9.39942726273345E-05" ixy="-2.93181599029908E-07" ixz="1.73270940326199E-05" iyy="0.000113244406627227" iyz="-3.14838914806693E-10" izz="8.10585911724992E-05"/>
      </inertial>
      <visual>
        <origin rpy="0 0 0" xyz="0 0 0"/>
        <geometry>
          <mesh filename="package://limbarm-robot/meshes/Link_5.STL"/>
        </geometry>
        <material name="">
          <color rgba="1 1 1 1"/>
        </material>
      </visual>
      <collision>
        <origin rpy="0 0 0" xyz="0 0 0"/>
        <geometry>
          <mesh filename="package://limbarm-robot/meshes/Link_5.STL"/>
        </geometry>
      </collision>
  </link>
  <joint name="Joint3_5" type="revolute">
      <origin rpy="3.1416 -1.5708 0" xyz="0 0 0.1795"/>
      <parent link="Link3_4"/>
      <child link="Link3_5"/>
      <axis xyz="0 0 1"/>
      <limit effort="0" lower="-1.9198621771937623" upper="1.9198621771937623" velocity="0"/>
  </joint>
  <link name="Link3_6">
      <inertial>
        <origin rpy="0 0 0" xyz="0.000146447962600783 0.000132910316064216 0.0194222181514005"/>
        <mass value="0.134599349728801"/>
        <inertia ixx="5.54993019233277E-05" ixy="-3.42434491188341E-07" ixz="1.1735586211374E-07" iyy="5.54034726867672E-05" iyz="9.38344787747327E-08" izz="9.77383386331803E-05"/>
      </inertial>
      <visual>
        <origin rpy="0 0 0" xyz="0 0 0"/>
        <geometry>
          <mesh filename="package://limbarm-robot/meshes/Link_6.STL"/>
        </geometry>
        <material name="">
          <color rgba="1 1 1 1"/>
        </material>
      </visual>
      <collision>
        <origin rpy="0 0 0" xyz="0 0 0"/>
        <geometry>
          <mesh filename="package://limbarm-robot/meshes/Link_6.STL"/>
        </geometry>
      </collision>
  </link>
  <joint name="Joint3_6" type="revolute">
      <origin rpy="0 1.5708 0" xyz="0.141 0 0"/>
      <parent link="Link3_5"/>
      <child link="Link3_6"/>
      <axis xyz="0 0 1"/>
      <limit effort="0" lower="-3.141592653589793" upper="3.141592653589793" velocity="0"/>
  </joint>
  <link name="Link3_Hand">
      <inertial>
        <origin rpy="0 0 0" xyz="-5.34486019601772E-05 -0.00163292800302499 0.0718038327986019"/>
        <mass value="0.306213518195145" />
        <inertia ixx="0.000241886583337232" ixy="-7.53752414578879E-06" ixz="-4.09966232551133E-08" iyy="0.000127174038942717" iyz="1.77993490423381E-06" izz="0.000271550204634038" />
      </inertial>
      <visual>
        <origin rpy="0 0 0" xyz="0 0 0"/>
        <geometry>
          <mesh filename="package://limbarm-robot/meshes/Hand.STL" />
        </geometry>
        <material name="">
          <color rgba="1 1 1 1" />
        </material>
      </visual>
      <collision>
        <origin rpy="0 0 0" xyz="0 0 0"/>
        <geometry>
          <mesh
            filename="package://limbarm-robot/meshes/Hand.STL" />
        </geometry>
      </collision>
  </link>
  <joint name="Joint3_hand"
      type="fixed">
      <origin rpy="0 0 0" xyz="0 0 0.0385"/>
      <parent link="Link3_6" />
      <child link="Link3_Hand" />
      <axis xyz="0 0 0" />
  </joint>
  <link name="Link4_0">
      <inertial>
        <origin rpy="0 0 0" xyz="0.0664169606230434 -0.0201281947592238 4.76216409223294E-09"/>
        <mass value="0.167855923175507"/>
        <inertia ixx="0.000138967813923233" ixy="0.00013034966620524" ixz="4.19274572448473E-10" iyy="0.000359258276622689" iyz="-4.93247675598086E-10" izz="0.00040872901975892"/>
      </inertial>
      <visual>
        <origin rpy="0 0 0" xyz="0 0 0"/>
        <geometry>
          <mesh filename="package://limbarm-robot/meshes/Link_0.STL"/>
        </geometry>
        <material name="">
          <color rgba="0.898039215686275 0.917647058823529 0.929411764705882 1"/>
        </material>
      </visual>
      <collision>
        <origin rpy="0 0 0" xyz="0 0 0"/>
        <geometry>
          <mesh filename="package://limbarm-robot/meshes/Link_0.STL"/>
        </geometry>
      </collision>
  </link>
  <joint name="Joint4_0" type="revolute">
      <origin rpy="1.5708 0 -2.3562" xyz="-0.072125 -0.072125 0.018"/>
      <parent link="base_link"/>
      <child link="Link4_0"/>
      <axis xyz="0 0 1"/>
      <limit effort="0" lower="0" upper="1.5707963267948966" velocity="0"/>
  </joint>
  <link name="Link4_1">
      <inertial>
        <origin rpy="0 0 0" xyz="0.0250848566132372 0.00345843485933482 0.0514637195946037"/>
        <mass value="0.0924049155630686"/>
        <inertia ixx="0.000113655728960563" ixy="-5.80244611122902E-06" ixz="-3.76444889979073E-06" iyy="0.000108121821578899" iyz="-3.49900344610929E-10" izz="9.35026260489851E-05"/>
      </inertial>
      <visual>
        <origin rpy="0 0 0" xyz="0 0 0"/>
        <geometry>
          <mesh filename="package://limbarm-robot/meshes/Link_1.STL"/>
        </geometry>
        <material name="">
          <color rgba="1 1 1 1"/>
        </material>
      </visual>
      <collision>
        <origin rpy="0 0 0" xyz="0 0 0"/>
        <geometry>
          <mesh filename="package://limbarm-robot/meshes/Link_1.STL"/>
        </geometry>
      </collision>
  </link>
  <joint name="Joint4_1" type="revolute">
      <origin rpy="1.5708 0 0" xyz="0.12 -0.058 0"/>
      <parent link="Link4_0"/>
      <child link="Link4_1"/>
      <axis xyz="0 0 1"/>
      <limit effort="0" lower="-2.094395102393195" upper="2.094395102393195" velocity="0"/>
  </joint>
  <link name="Link4_2">
      <inertial>
        <origin rpy="0 0 0" xyz="0.164755159604738 5.52891938350869E-05 0.00408065381894232"/>
        <mass value="0.199013621726556"/>
        <inertia ixx="0.000157061185619374" ixy="1.12205157240906E-10" ixz="1.68248403114826E-05" iyy="0.000550518166051161" iyz="3.11728051125751E-11" izz="0.000520833679086167"/>
      </inertial>
      <visual>
        <origin rpy="0 0 0" xyz="0 0 0"/>
        <geometry>
          <mesh filename="package://limbarm-robot/meshes/Link_2.STL"/>
        </geometry>
        <material name="">
          <color rgba="1 1 1 1"/>
        </material>
      </visual>
      <collision>
        <origin rpy="0 0 0" xyz="0 0 0"/>
        <geometry>
          <mesh filename="package://limbarm-robot/meshes/Link_2.STL"/>
        </geometry>
      </collision>
  </link>
  <joint name="Joint4_2" type="revolute">
      <origin rpy="-1.5708 0 0" xyz="0.0625 0.0025 0.059"/>
      <parent link="Link4_1"/>
      <child link="Link4_2"/>
      <axis xyz="0 0 1"/>
      <limit effort="0" lower="-2.0943951023931953" upper="1.5707963267948966" velocity="0"/>
  </joint>
  <link name="Link4_3">
      <inertial>
        <origin rpy="0 0 0" xyz="0.0720097797375396 -0.000448350531068148 0.00124427030485257"/>
        <mass value="0.133696366167161"/>
        <inertia ixx="0.000115445322405323" ixy="-2.9390750086264E-07" ixz="3.41837661585693E-05" iyy="0.000205794166012378" iyz="-7.33953327793886E-11" izz="0.000182900509037997"/>
      </inertial>
      <visual>
        <origin rpy="0 0 0" xyz="0 0 0"/>
        <geometry>
          <mesh filename="package://limbarm-robot/meshes/Link_3.STL"/>
        </geometry>
        <material name="">
          <color rgba="1 1 1 1"/>
        </material>
      </visual>
      <collision>
        <origin rpy="0 0 0" xyz="0 0 0"/>
        <geometry>
          <mesh filename="package://limbarm-robot/meshes/Link_3.STL"/>
        </geometry>
      </collision>
  </link>
  <joint name="Joint4_3" type="revolute">
      <origin rpy="0 0 0" xyz="0.35 0.0002 0"/>
      <parent link="Link4_2"/>
      <child link="Link4_3"/>
      <axis xyz="0 0 1"/>
      <limit effort="0" lower="-2.530727415391778" upper="2.530727415391778" velocity="0"/>
  </joint>
  <link name="Link4_4">
      <inertial>
        <origin rpy="0 0 0" xyz="-0.00219595597659072 5.55111512312578E-17 0.10937323066911"/>
        <mass value="0.0991853302135674"/>
        <inertia ixx="0.000103997514125068" ixy="-1.20729995670382E-20" ixz="4.04878902852236E-06" iyy="0.000118364894914693" iyz="2.39343771466793E-20" izz="7.06314967499001E-05"/>
      </inertial>
      <visual>
        <origin rpy="0 0 0" xyz="0 0 0"/>
        <geometry>
          <mesh filename="package://limbarm-robot/meshes/Link_4.STL"/>
        </geometry>
        <material name="">
          <color rgba="1 1 1 1"/>
        </material>
      </visual>
      <collision>
        <origin rpy="0 0 0" xyz="0 0 0"/>
        <geometry>
          <mesh filename="package://limbarm-robot/meshes/Link_4.STL"/>
        </geometry>
      </collision>
  </link>
  <joint name="Joint4_4" type="revolute">
      <origin rpy="0 1.5708 0" xyz="0.1745 0 0"/>
      <parent link="Link4_3"/>
      <child link="Link4_4"/>
      <axis xyz="0 0 1"/>
      <limit effort="0" lower="-3.141592653589793" upper="3.141592653589793" velocity="0"/>
  </joint>
  <link name="Link4_5">
      <inertial>
        <origin rpy="0 0 0" xyz="0.0516421278227287 -0.000601786312485739 0.00160323320931993"/>
        <mass value="0.102911752371677"/>
        <inertia ixx="9.39942726273345E-05" ixy="-2.93181599029908E-07" ixz="1.73270940326199E-05" iyy="0.000113244406627227" iyz="-3.14838914806693E-10" izz="8.10585911724992E-05"/>
      </inertial>
      <visual>
        <origin rpy="0 0 0" xyz="0 0 0"/>
        <geometry>
          <mesh filename="package://limbarm-robot/meshes/Link_5.STL"/>
        </geometry>
        <material name="">
          <color rgba="1 1 1 1"/>
        </material>
      </visual>
      <collision>
        <origin rpy="0 0 0" xyz="0 0 0"/>
        <geometry>
          <mesh filename="package://limbarm-robot/meshes/Link_5.STL"/>
        </geometry>
      </collision>
  </link>
  <joint name="Joint4_5" type="revolute">
      <origin rpy="3.1416 -1.5708 0" xyz="0 0 0.1795"/>
      <parent link="Link4_4"/>
      <child link="Link4_5"/>
      <axis xyz="0 0 1"/>
      <limit effort="0" lower="-1.9198621771937623" upper="1.9198621771937623" velocity="0"/>
  </joint>
  <link name="Link4_6">
      <inertial>
        <origin rpy="0 0 0" xyz="0.000146447962600783 0.000132910316064216 0.0194222181514005"/>
        <mass value="0.134599349728801"/>
        <inertia ixx="5.54993019233277E-05" ixy="-3.42434491188341E-07" ixz="1.1735586211374E-07" iyy="5.54034726867672E-05" iyz="9.38344787747327E-08" izz="9.77383386331803E-05"/>
      </inertial>
      <visual>
        <origin rpy="0 0 0" xyz="0 0 0"/>
        <geometry>
          <mesh filename="package://limbarm-robot/meshes/Link_6.STL"/>
        </geometry>
        <material name="">
          <color rgba="1 1 1 1"/>
        </material>
      </visual>
      <collision>
        <origin rpy="0 0 0" xyz="0 0 0"/>
        <geometry>
          <mesh filename="package://limbarm-robot/meshes/Link_6.STL"/>
        </geometry>
      </collision>
  </link>
  <joint name="Joint4_6" type="revolute">
      <origin rpy="0 1.5708 0" xyz="0.141 0 0"/>
      <parent link="Link4_5"/>
      <child link="Link4_6"/>
      <axis xyz="0 0 1"/>
      <limit effort="0" lower="-3.141592653589793" upper="3.141592653589793" velocity="0"/>
  </joint>
  <link name="Link4_Hand">
      <inertial>
        <origin rpy="0 0 0" xyz="-5.34486019601772E-05 -0.00163292800302499 0.0718038327986019"/>
        <mass value="0.306213518195145" />
        <inertia ixx="0.000241886583337232" ixy="-7.53752414578879E-06" ixz="-4.09966232551133E-08" iyy="0.000127174038942717" iyz="1.77993490423381E-06" izz="0.000271550204634038" />
      </inertial>
      <visual>
        <origin rpy="0 0 0" xyz="0 0 0"/>
        <geometry>
          <mesh filename="package://limbarm-robot/meshes/Hand.STL" />
        </geometry>
        <material name="">
          <color rgba="1 1 1 1" />
        </material>
      </visual>
      <collision>
        <origin rpy="0 0 0" xyz="0 0 0"/>
        <geometry>
          <mesh
            filename="package://limbarm-robot/meshes/Hand.STL" />
        </geometry>
      </collision>
  </link>
  <joint name="Joint4_hand"
      type="fixed">
      <origin rpy="0 0 0" xyz="0 0 0.0385"/>
      <parent link="Link4_6" />
      <child link="Link4_Hand" />
      <axis xyz="0 0 0" />
  </joint>
  <!-- <link name="Link1_platlink">
      <inertial>
        <origin rpy="0 0 0" xyz="0.0289156328970307 -0.0118446128560949 0.000499999999999173"/>
        <mass value="0.0220769548357911"/>
        <inertia ixx="2.37550123797196E-06" ixy="4.94134205566748E-06" ixz="9.82725726587017E-22" iyy="1.24144355257915E-05" iyz="-1.77130197123773E-22" izz="1.46210848148476E-05"/>
      </inertial>
      <visual>
        <origin rpy="0 0 0" xyz="0 0 0"/>
        <geometry>
          <mesh filename="package://limbarm-robot/meshes/Link_platlink.STL"/>
        </geometry>
        <material name="">
          <color rgba="0.898039215686275 0.917647058823529 0.929411764705882 1"/>
        </material>
      </visual>
      <collision>
        <origin rpy="0 0 0" xyz="0 0 0"/>
        <geometry>
          <mesh filename="package://limbarm-robot/meshes/Link_platlink.STL"/>
        </geometry>
      </collision>
  </link>
  <joint name="Joint1_platlink" type="revolute">
      <origin rpy="1.5708 0 0.7854" xyz="0.056569 0.056569 0"/>
      <parent link="Link_platform"/>
      <child link="Link1_platlink"/>
      <axis xyz="0 0 1"/>
      <limit effort="0" lower="-1.5707963267948966" upper="0" velocity="0"/>
  </joint>
  <link name="Link2_platlink">
      <inertial>
        <origin rpy="0 0 0" xyz="0.0289156328970307 -0.0118446128560949 0.000499999999999173"/>
        <mass value="0.0220769548357911"/>
        <inertia ixx="2.37550123797196E-06" ixy="4.94134205566748E-06" ixz="9.82725726587017E-22" iyy="1.24144355257915E-05" iyz="-1.77130197123773E-22" izz="1.46210848148476E-05"/>
      </inertial>
      <visual>
        <origin rpy="0 0 0" xyz="0 0 0"/>
        <geometry>
          <mesh filename="package://limbarm-robot/meshes/Link_platlink.STL"/>
        </geometry>
        <material name="">
          <color rgba="0.898039215686275 0.917647058823529 0.929411764705882 1"/>
        </material>
      </visual>
      <collision>
        <origin rpy="0 0 0" xyz="0 0 0"/>
        <geometry>
          <mesh filename="package://limbarm-robot/meshes/Link_platlink.STL"/>
        </geometry>
      </collision>
  </link>
  <joint name="Joint2_platlink" type="revolute">
      <origin rpy="1.5708 0 2.3562" xyz="-0.056569 0.056569 0"/>
      <parent link="Link_platform"/>
      <child link="Link2_platlink"/>
      <axis xyz="0 0 1"/>
      <limit effort="0" lower="-1.5707963267948966" upper="0" velocity="0"/>
  </joint>
  <link name="Link3_platlink">
      <inertial>
        <origin rpy="0 0 0" xyz="0.0289156328970307 -0.0118446128560949 0.000499999999999173"/>
        <mass value="0.0220769548357911"/>
        <inertia ixx="2.37550123797196E-06" ixy="4.94134205566748E-06" ixz="9.82725726587017E-22" iyy="1.24144355257915E-05" iyz="-1.77130197123773E-22" izz="1.46210848148476E-05"/>
      </inertial>
      <visual>
        <origin rpy="0 0 0" xyz="0 0 0"/>
        <geometry>
          <mesh filename="package://limbarm-robot/meshes/Link_platlink.STL"/>
        </geometry>
        <material name="">
          <color rgba="0.898039215686275 0.917647058823529 0.929411764705882 1"/>
        </material>
      </visual>
      <collision>
        <origin rpy="0 0 0" xyz="0 0 0"/>
        <geometry>
          <mesh filename="package://limbarm-robot/meshes/Link_platlink.STL"/>
        </geometry>
      </collision>
  </link>
  <joint name="Joint3_platlink" type="revolute">
      <origin rpy="1.5708 0 -0.7854" xyz="0.056569 -0.056569 0"/>
      <parent link="Link_platform"/>
      <child link="Link3_platlink"/>
      <axis xyz="0 0 1"/>
      <limit effort="0" lower="-1.5707963267948966" upper="0" velocity="0"/>
  </joint>
  <link name="Link4_platlink">
      <inertial>
        <origin rpy="0 0 0" xyz="0.0289156328970307 -0.0118446128560949 0.000499999999999173"/>
        <mass value="0.0220769548357911"/>
        <inertia ixx="2.37550123797196E-06" ixy="4.94134205566748E-06" ixz="9.82725726587017E-22" iyy="1.24144355257915E-05" iyz="-1.77130197123773E-22" izz="1.46210848148476E-05"/>
      </inertial>
      <visual>
        <origin rpy="0 0 0" xyz="0 0 0"/>
        <geometry>
          <mesh filename="package://limbarm-robot/meshes/Link_platlink.STL"/>
        </geometry>
        <material name="">
          <color rgba="0.898039215686275 0.917647058823529 0.929411764705882 1"/>
        </material>
      </visual>
      <collision>
        <origin rpy="0 0 0" xyz="0 0 0"/>
        <geometry>
          <mesh filename="package://limbarm-robot/meshes/Link_platlink.STL"/>
        </geometry>
      </collision>
  </link>
  <joint name="Joint4_platlink" type="revolute">
      <origin rpy="1.5708 0 -2.3562" xyz="-0.056569 -0.056569 0"/>
      <parent link="Link_platform"/>
      <child link="Link4_platlink"/>
      <axis xyz="0 0 1"/>
      <limit effort="0" lower="-1.5707963267948966" upper="0" velocity="0"/>
  </joint> -->
</robot>

