<?xml version="1.0" ?>
<robot name="single_arm">
  <link name="base_link">
    <inertial>
      <origin rpy="0 0 0" xyz="0.085427 -0.025518 0"/>
      <mass value="0.960"/>
      <inertia ixx="0.000648473" ixy="-0.001018876" ixz="0.000012959" iyy="0.002674366" iyz="0" izz="0.003031056"/>
    </inertial>
    <!--重心:(毫米)	X = 85.427 Y = -25.518 Z = -0.131
    惯性张量: (千克*平方毫米)由重心决定，并且对齐输出的坐标系。Lxx = 648.473	Lxy = -1018.876	Lxz = 12.959 Lyy = 2674.366	Lyz = 0.781	Lzz = 3031.056-->
    <visual>
      <origin rpy="0 0 0" xyz="0 0 0"/>
      <geometry>
        <mesh filename="package://robot_3dros/meshes/Link_0.STL"/>
      </geometry>
      <material name="">
        <color rgba="0 1 1 1"/>
      </material>
    </visual>
    <!--collision>
      <origin xyz="0 0 0" rpy="0 0 0" />
      <geometry> <mesh filename="package://robot_3dros/meshes/Link_0.STL" /> </geometry>
    </collision-->
  </link>
  <link name="Link1_1">
    <inertial>
      <origin rpy="0 0 0" xyz="0.052469 -0.009040 0.002060"/>
      <mass value="0.914"/>
      <inertia ixx="0.000671687" ixy="-0.000084224" ixz="-0.000107815" iyy="0.000786758" iyz="0.000017298" izz="0.000958254"/>
    </inertial>
    <!--重心:(毫米)	X = 52.469 Y = -9.040	Z = 2.060
    惯性张量:(千克*平方毫米)由重心决定，并且对齐输出的坐标系。Lxx = 671.687	Lxy = -84.224	Lxz = -107.815 Lyy = 786.758 Lyz = 17.298	Lzz = 958.254-->
    <visual>
      <origin rpy="0 0 0" xyz="0 0 0"/>
      <geometry>
        <mesh filename="package://robot_3dros/meshes/Link_1.STL"/>
      </geometry>
      <material name="">
        <color rgba="1 1 1 1"/>
      </material>
    </visual>
    <!--collision>
      <origin xyz="0 0 0" rpy="0 0 0" />
      <geometry> <mesh filename="package://robot_3dros/meshes/Link_1.STL" /> </geometry>
    </collision-->
  </link>
  <joint name="Joint1_1" type="revolute">
    <origin rpy="-1.5707963267948966 0 0" xyz="0.12 -0.117 0"/>
    <parent link="base_link"/>
    <child link="Link1_1"/>
    <axis xyz="0 0 1"/>
    <dynamics damping="0.2" friction="0.5"/>
    <limit effort="300" lower="-2.356194490192345" upper="4.71238898038469" velocity="10"/>
  </joint>
  <link name="Link1_2">
    <inertial>
      <origin rpy="0 0 0" xyz="0.273270 0.000006 0.007530"/>
      <mass value="1.144"/>
      <inertia ixx="0.000909959" ixy="0" ixz="0.000569994" iyy="0.018834040" iyz="0" izz="0.018336908"/>
    </inertial>
    <!--重心:(毫米)	X = 273.270	Y = 0.006	Z = 7.530
    惯性张量:(千克*平方毫米)由重心决定，并且对齐输出的坐标系。Lxx = 909.959	Lxy = 0.824	Lxz = 569.994	Lyy = 18834.040	Lyz = 0.056	Lzz = 18336.908-->
    <visual>
      <origin rpy="0 0 0" xyz="0 0 0"/>
      <geometry>
        <mesh filename="package://robot_3dros/meshes/Link_2.STL"/>
      </geometry>
      <material name="">
        <color rgba="1 1 1 1"/>
      </material>
    </visual>
    <collision>
      <origin rpy="0 1.5707963267948966 0" xyz="0.155 0 0"/>
      <geometry>
        <cylinder length="0.3" radius="0.02"/>
      </geometry>
      <!--geometry> <mesh filename="package://robot_3dros/meshes/Link_2.STL" /> </geometry-->
    </collision>
  </link>
  <joint name="Joint1_2" type="revolute">
    <origin rpy="1.5707963267948966 0 0" xyz="0.0625 -0.0025 0"/>
    <parent link="Link1_1"/>
    <child link="Link1_2"/>
    <axis xyz="0 0 1"/>
    <dynamics damping="0.2" friction="0.5"/>
    <limit effort="300" lower="-2.0943951023931953" upper="1.5707963267948966" velocity="10"/>
  </joint>
  <link name="Link1_3">
    <inertial>
      <origin rpy="0 0 0" xyz="0.081336 -0.0003 -0.000693"/>
      <mass value="0.395"/>
      <inertia ixx="0.000576423" ixy="0" ixz="0.000031283" iyy="0.001662107" iyz="0" izz="0.001334389"/>
    </inertial>
    <!--重心:(毫米)	X = 81.336 Y = -0.003	Z = -0.693
    惯性张量:(千克*平方毫米)由重心决定，并且对齐输出的坐标系。Lxx = 576.423	Lxy = -0.053 Lxz = 31.283 Lyy = 1662.107	Lyz = -0.009 Lzz = 1334.389-->
    <visual>
      <origin rpy="0 0 0" xyz="0 0 0"/>
      <geometry>
        <mesh filename="package://robot_3dros/meshes/Link_3.STL"/>
      </geometry>
      <material name="">
        <color rgba="1 1 1 1"/>
      </material>
    </visual>
    <collision>
      <origin rpy="0 1.5707963267948966 0" xyz="0.16 0 0"/>
      <geometry>
        <cylinder length="0.2" radius="0.02"/>
      </geometry>
      <!--geometry> <mesh filename="package://robot_3dros/meshes/Link_3.STL" /> </geometry-->
    </collision>
  </link>
  <joint name="Joint1_3" type="revolute">
    <origin rpy="-3.141592653589793 0 0" xyz="0.35 0.0002 0"/>
    <parent link="Link1_2"/>
    <child link="Link1_3"/>
    <axis xyz="0 0 1"/>
    <dynamics damping="0.2" friction="0.5"/>
    <limit effort="300" lower="-2.530727415391778" upper="2.530727415391778" velocity="10"/>
  </joint>
  <link name="Link1_4">
    <inertial>
      <origin rpy="0 0 0" xyz="0.005438 0.000120 0.134002"/>
      <mass value="0.376"/>
      <inertia ixx="0.0001484574" ixy="0" ixz="0.000099045" iyy="0.001658464" iyz="-0.000002871" izz="0.000360737"/>
    </inertial>
    <!--重心:(毫米)	X = 5.438	Y = 0.120	Z = 134.002
    惯性张量:(千克*平方毫米)由重心决定，并且对齐输出的坐标系。Lxx = 1484.574	Lxy = -0.250 Lxz = 99.045 Lyy = 1658.464 Lyz = -2.871 Lzz = 360.737-->
    <visual>
      <origin rpy="0 0 0" xyz="0 0 0"/>
      <geometry>
        <mesh filename="package://robot_3dros/meshes/Link_4.STL"/>
      </geometry>
      <material name="">
        <color rgba="1 1 1 1"/>
      </material>
    </visual>
    <!--collision>
      <origin xyz="0 0 0.08" rpy="0 0 0" />
      <geometry> <mesh filename="package://robot_3dros/meshes/Link_4.STL" /> </geometry>
    </collision-->
  </link>
  <joint name="Joint1_4" type="revolute">
    <origin rpy="0 -1.5707963267948966 -3.141592653589793" xyz="0.1745 0 0"/>
    <parent link="Link1_3"/>
    <child link="Link1_4"/>
    <axis xyz="0 0 1"/>
    <dynamics damping="0.2" friction="0.5"/>
    <limit effort="100" lower="-3.141592653589793" upper="3.141592653589793" velocity="10"/>
  </joint>
  <link name="Link1_5">
    <inertial>
      <origin rpy="0 0 0" xyz="0.058277 0 -0.001068"/>
      <mass value="0.327"/>
      <inertia ixx="0.000412080" ixy="0" ixz="0.000002889" iyy="0.000943104" iyz="0" izz="0.000708641"/>
    </inertial>
    <!--重心:(毫米)	X = 58.277 Y = 0.004 Z = -1.068
        惯性张量:(千克*平方毫米)由重心决定，并且对齐输出的坐标系。Lxx = 412.080	Lxy = 0.032	Lxz = 2.889	Lyy = 943.104	Lyz = -0.003 Lzz = 708.641-->
    <visual>
      <origin rpy="0 0 0" xyz="0 0 0"/>
      <geometry>
        <mesh filename="package://robot_3dros/meshes/Link_5.STL"/>
      </geometry>
      <material name="">
        <color rgba="1 1 1 1"/>
      </material>
    </visual>
    <!--collision>
      <origin xyz="0.08 0 0" rpy="0 0 0" />
      <geometry> <mesh filename="package://robot_3dros/meshes/Link_5.STL" /> </geometry>
    </collision-->
  </link>
  <joint name="Joint1_5" type="revolute">
    <origin rpy="3.141592653589793 -1.5707963267948966 0" xyz="0 0 0.1795"/>
    <parent link="Link1_4"/>
    <child link="Link1_5"/>
    <axis xyz="0 0 1"/>
    <dynamics damping="0.2" friction="0.5"/>
    <limit effort="100" lower="-1.9198621771937623" upper="1.9198621771937623" velocity="10"/>
  </joint>
  <link name="Link1_6">
    <inertial>
      <origin rpy="0 0 0" xyz="-0.000076 -0.001467 0.088450"/>
      <mass value="0.366"/>
      <inertia ixx="0.000945510" ixy="-0.000011196" ixz="0" iyy="0.000811306" iyz="-0.000011704" izz="0.000402389"/>
    </inertial>
    <!--重心:(毫米)	X = -0.094 Y = -1.809 Z = 70.443
    惯性张量:(千克*平方毫米)由重心决定，并且对齐输出的坐标系。Lxx = 945.510	Lxy = -11.196	Lxz = -0.115	Lyy = 811.306	Lyz = -11.704	Lzz = 402.389-->
    <visual>
      <origin rpy="0 0 0" xyz="0 0 0"/>
      <geometry>
        <mesh filename="package://robot_3dros/meshes/Link_6.STL"/>
      </geometry>
      <material name="">
        <color rgba="1 1 1 1"/>
      </material>
    </visual>
    <collision>
      <origin rpy="0 0 0" xyz="0 0 -0.06"/>
      <geometry>
        <cylinder length="0.1" radius="0.02"/>
      </geometry>
      <!--geometry> <mesh filename="package://robot_3dros/meshes/Link_6.STL" /> </geometry-->
    </collision>
  </link>
  <joint name="Joint1_6" type="revolute">
    <origin rpy="3.141592653589793 -1.5707963267948966 0" xyz="0.141 0 0"/>
    <parent link="Link1_5"/>
    <child link="Link1_6"/>
    <axis xyz="0 0 1"/>
    <dynamics damping="0.2" friction="0.5"/>
    <limit effort="100" lower="-3.141592653589793" upper="3.141592653589793" velocity="10"/>
  </joint>
</robot>

