<?xml version="1.0" ?>
<!-- =================================================================================== -->
<!-- |    This document was autogenerated by xacro from robot_description.xacro        | -->
<!-- |    EDITING THIS FILE BY HAND IS NOT RECOMMENDED                                 | -->
<!-- =================================================================================== -->
<!-- This URDF was automatically created by SolidWorks to URDF Exporter! Originally created by Stephen Brawner (brawner@gmail.com) 
     Commit Version: 1.6.0-1-g15f4949  Build Version: 1.6.7594.29634
     For more information, please see http://wiki.ros.org/sw_urdf_exporter -->
<robot name="robot_description">
    <!--body*********************************************************************************************************-->
    <!-- <link name="world" /> -->

    <link name="base_link">
        <inertial>
            <origin rpy="0 0 0" xyz="0 0 0.042" />
            <mass value="1.492" />
            <inertia ixx="0.004886486" ixy="-0.000017397" ixz="-0.000263075" iyy="0.004100237" iyz="0" izz="0.003937989" />
        </inertial>
        <visual>
            <origin rpy="0 0 0" xyz="0 0 0" />
            <geometry>
                <mesh filename="package://robot_description/meshes/base_link.STL" />
            </geometry>
            <material name="">
                <color rgba="0.75294 0.75294 0.75294 1" />
            </material>
        </visual>
        <collision>
            <origin rpy="0 0 0" xyz="0 0 0" />
            <geometry>
                <mesh filename="package://robot_description/meshes/base_link.STL" />
            </geometry>
            <surface>
                <friction>
                    <torsional>
                        <coefficient>5.0</coefficient>
                        <surface_radius>0.10</surface_radius>
                        <use_patch_radius>false</use_patch_radius>
                    </torsional>
                </friction>
            </surface>
        </collision>
    </link>
    <!-- <joint name="world_to_truss_link" type="fixed">
        <parent link="world" />
        <child link="truss_link" />
        <origin rpy="1.5708 0 3.1415" xyz="0.6625 0 0" />
    </joint>
    <link name="truss_link">
        <inertial>
            <origin rpy="0 0 0" xyz="0.36747875296263 -0.0267703008644749 2.17639122268576E-06" />
            <mass value="21.7746312239973" />
            <inertia ixx="6.13854571738268" ixy="0.0126716758688149" ixz="-0.000126373819517297" iyy="16.7375552194284" iyz="-1.43555608026521E-06" izz="10.6624119014708" />
        </inertial>
        <visual>
            <origin rpy="0 0 0" xyz="0 0 0" />
            <geometry>
                <mesh filename="package://robot_description/meshes/truss_link.STL" />
            </geometry>
            <material name="">
                <color rgba="0.792156862745098 0.819607843137255 0.933333333333333 1" />
            </material>
        </visual>
        <collision>
            <origin rpy="0 0 0" xyz="0 0 0" />
            <geometry>
                <mesh filename="package://robot_description/meshes/truss_link.STL" />
            </geometry>
        </collision>
    </link>
    <link name="dummy_point1" />
    <joint name="truss_link_to_point1" type="fixed">
        <parent link="truss_link" />
        <child link="dummy_point1" />
        <origin rpy="1.5708 0 0" xyz="0.795 0 0.53" />
    </joint>
    <link name="dummy_point2" />
    <joint name="truss_link_to_point2" type="fixed">
        <parent link="truss_link" />
        <child link="dummy_point2" />
        <origin rpy="1.5708 0 0" xyz="0.795 0 -0.53" />
    </joint>
    <link name="dummy_point3" />
    <joint name="truss_link_to_point3" type="fixed">
        <parent link="truss_link" />
        <child link="dummy_point3" />
        <origin rpy="1.5708 0.707 0" xyz="0.08 0.18 0.40" />
    </joint>
    <link name="dummy_point4" />
    <joint name="truss_link_to_point4" type="fixed">
        <parent link="truss_link" />
        <child link="dummy_point4" />
        <origin rpy="0 0 0" xyz="0 0.215 -0.3" />
    </joint>
    <link name="object" />
    <joint name="truss_link_to_obj" type="fixed">
        <parent link="truss_link" />
        <child link="object" />
        <origin rpy="1.5708 0.707 0" xyz="0.08 0.03 0.40" />
    </joint>
    <link name="object1" />
    <joint name="truss_link_to_obj1" type="fixed">
        <parent link="truss_link" />
        <child link="object1" />
        <origin rpy="0 3.1416 0" xyz="-0.1 0.215 0.085" />
    </joint>
    <link name="object2" />
    <joint name="truss_link_to_obj2" type="fixed">
        <parent link="truss_link" />
        <child link="object2" />
        <origin rpy="0 0 -1.5708" xyz="-0.265 0.215 -0.35" />
    </joint>
    <link name="cube_l" />
    <joint name="truss_link_to_cube_l" type="fixed">
        <parent link="truss_link" />
        <child link="cube_l" />
        <origin rpy="0 3.1416 0" xyz="-0.1175 0.12 0.2325" />
    </joint>
    <link name="cube_r" />
    <joint name="truss_link_to_cube_r" type="fixed">
        <parent link="truss_link" />
        <child link="cube_r" />
        <origin rpy="0 0 0" xyz="-0.1175 0.12 -0.2325" />
    </joint> -->
    <link name="Link_platform">
        <inertial>
            <origin rpy="0 0 0" xyz="0 0 0.011605" />
            <mass value="0.218" />
            <inertia ixx="0.000745872" ixy="0" ixz="0" iyy="0.000792081" iyz="0" izz="0.001494320" />
        </inertial>
        <visual>
            <origin rpy="0 0 0" xyz="0 0 0" />
            <geometry>
                <mesh filename="package://robot_description/meshes/Link_platform.STL" />
            </geometry>
            <material name="">
                <color rgba="0.75294 0.75294 0.75294 1" />
            </material>
        </visual>
        <collision>
            <origin rpy="0 0 0" xyz="0 0 0" />
            <geometry>
                <mesh filename="package://robot_description/meshes/Link_platform.STL" />
            </geometry>
        </collision>
    </link>
    <joint name="Joint_platform" type="prismatic">
        <origin rpy="0 0 0" xyz="0 0 0.043397" />
        <parent link="base_link" />
        <child link="Link_platform" />
        <axis xyz="0 0 1" />
        <dynamics damping="0.1" friction="0.8" />
        <limit effort="1000" lower="0" upper="0.5" velocity="10" />
    </joint>
    <link name="Link1_0">
        <inertial>
            <origin rpy="0 0 0" xyz="0.085427 -0.025518 0" />
            <mass value="0.960" />
            <inertia ixx="0.000648473" ixy="-0.001018876" ixz="0.000012959" iyy="0.002674366" iyz="0" izz="0.003031056" />
        </inertial>
        <visual>
            <origin rpy="0 0 0" xyz="0 0 0" />
            <geometry>
                <mesh filename="package://robot_description/meshes/Link_0.STL" />
            </geometry>
            <material name="">
                <color rgba="0 1 1 1" />
            </material>
        </visual>
        <collision>
            <origin rpy="0 0 0" xyz="0 0 0" />
            <geometry>
                <mesh filename="package://robot_description/meshes/Link_0.STL" />
            </geometry>
        </collision>
    </link>
    <joint name="Joint1_0" type="revolute">
        <origin rpy="1.5707963267948966 0 0.7853981633974483" xyz="0.072125 0.072125 0.018" />
        <parent link="base_link" />
        <child link="Link1_0" />
        <axis xyz="0 0 1" />
        <dynamics damping="0.1" friction="0.8" />
        <limit effort="1000" lower="0" upper="1.5707963267948966" velocity="10" />
    </joint>
    <link name="Link1_1">
        <inertial>
            <origin rpy="0 0 0" xyz="0.052469 -0.009040 0.002060" />
            <mass value="0.914" />
            <inertia ixx="0.000671687" ixy="-0.000084224" ixz="-0.000107815" iyy="0.000786758" iyz="0.000017298" izz="0.000958254" />
        </inertial>
        <visual>
            <origin rpy="0 0 0" xyz="0 0 0" />
            <geometry>
                <mesh filename="package://robot_description/meshes/Link_1.STL" />
            </geometry>
            <material name="">
                <color rgba="1 1 1 1" />
            </material>
        </visual>
        <collision>
            <origin rpy="0 0 0" xyz="0 0 0" />
            <geometry>
                <mesh filename="package://robot_description/meshes/Link_1.STL" />
            </geometry>
        </collision>
    </link>
    <joint name="Joint1_1" type="revolute">
        <origin rpy="-1.5707963267948966 0 0" xyz="0.12 -0.117 0" />
        <parent link="Link1_0" />
        <child link="Link1_1" />
        <axis xyz="0 0 1" />
        <dynamics damping="0.1" friction="0.8" />
        <limit effort="300" lower="-2.356194490192345" upper="4.71238898038469" velocity="10" />
    </joint>
    <link name="Link1_2">
        <inertial>
            <origin rpy="0 0 0" xyz="0.273270 0.000006 0.007530" />
            <mass value="1.144" />
            <inertia ixx="0.000909959" ixy="0" ixz="0.000569994" iyy="0.018834040" iyz="0" izz="0.018336908" />
        </inertial>
        <visual>
            <origin rpy="0 0 0" xyz="0 0 0" />
            <geometry>
                <mesh filename="package://robot_description/meshes/Link_2.STL" />
            </geometry>
            <material name="">
                <color rgba="1 1 1 1" />
            </material>
        </visual>
        <collision>
            <origin rpy="0 0 0" xyz="0 0 0" />
            <geometry>
                <mesh filename="package://robot_description/meshes/Link_2.STL" />
            </geometry>
        </collision>
    </link>
    <joint name="Joint1_2" type="revolute">
        <origin rpy="1.5707963267948966 0 0" xyz="0.0625 -0.0025 0" />
        <parent link="Link1_1" />
        <child link="Link1_2" />
        <axis xyz="0 0 1" />
        <dynamics damping="0.1" friction="0.8" />
        <limit effort="300" lower="-2.0943951023931953" upper="1.5707963267948966" velocity="10" />
    </joint>
    <link name="Link1_3">
        <inertial>
            <origin rpy="0 0 0" xyz="0.081336 -0.0003 -0.000693" />
            <mass value="0.395" />
            <inertia ixx="0.000576423" ixy="0" ixz="0.000031283" iyy="0.001662107" iyz="0" izz="0.001334389" />
        </inertial>
        <visual>
            <origin rpy="0 0 0" xyz="0 0 0" />
            <geometry>
                <mesh filename="package://robot_description/meshes/Link_3.STL" />
            </geometry>
            <material name="">
                <color rgba="1 1 1 1" />
            </material>
        </visual>
        <collision>
            <origin rpy="0 0 0" xyz="0 0 0" />
            <geometry>
                <mesh filename="package://robot_description/meshes/Link_3.STL" />
            </geometry>
        </collision>
    </link>
    <joint name="Joint1_3" type="revolute">
        <origin rpy="-3.141592653589793 0 0" xyz="0.35 0.0002 0" />
        <parent link="Link1_2" />
        <child link="Link1_3" />
        <axis xyz="0 0 1" />
        <dynamics damping="0.1" friction="0.8" />
        <limit effort="300" lower="-2.530727415391778" upper="2.530727415391778" velocity="10" />
    </joint>
    <link name="Link1_4">
        <inertial>
            <origin rpy="0 0 0" xyz="0.005438 0.000120 0.134002" />
            <mass value="0.376" />
            <inertia ixx="0.0001484574" ixy="0" ixz="0.000099045" iyy="0.001658464" iyz="-0.000002871" izz="0.000360737" />
        </inertial>
        <visual>
            <origin rpy="0 0 0" xyz="0 0 0" />
            <geometry>
                <mesh filename="package://robot_description/meshes/Link_4.STL" />
            </geometry>
            <material name="">
                <color rgba="1 1 1 1" />
            </material>
        </visual>
        <collision>
            <origin rpy="0 0 0" xyz="0 0 0" />
            <geometry>
                <mesh filename="package://robot_description/meshes/Link_4.STL" />
            </geometry>
        </collision>
    </link>
    <joint name="Joint1_4" type="revolute">
        <origin rpy="0 -1.5707963267948966 -3.141592653589793" xyz="0.1745 0 0" />
        <parent link="Link1_3" />
        <child link="Link1_4" />
        <axis xyz="0 0 1" />
        <dynamics damping="0.1" friction="0.8" />
        <limit effort="100" lower="-3.141592653589793" upper="3.141592653589793" velocity="10" />
    </joint>
    <link name="Link1_5">
        <inertial>
            <origin rpy="0 0 0" xyz="0.058277 0 -0.001068" />
            <mass value="0.327" />
            <inertia ixx="0.000412080" ixy="0" ixz="0.000002889" iyy="0.000943104" iyz="0" izz="0.000708641" />
        </inertial>
        <visual>
            <origin rpy="0 0 0" xyz="0 0 0" />
            <geometry>
                <mesh filename="package://robot_description/meshes/Link_5.STL" />
            </geometry>
            <material name="">
                <color rgba="1 1 1 1" />
            </material>
        </visual>
        <collision>
            <origin rpy="0 0 0" xyz="0 0 0" />
            <geometry>
                <mesh filename="package://robot_description/meshes/Link_5.STL" />
            </geometry>
        </collision>
    </link>
    <joint name="Joint1_5" type="revolute">
        <origin rpy="3.141592653589793 -1.5707963267948966 0" xyz="0 0 0.1795" />
        <parent link="Link1_4" />
        <child link="Link1_5" />
        <axis xyz="0 0 1" />
        <dynamics damping="0.1" friction="0.8" />
        <limit effort="100" lower="-1.9198621771937623" upper="1.9198621771937623" velocity="10" />
    </joint>
    <link name="Link1_6">
        <inertial>
            <origin rpy="0 0 0" xyz="-0.000076 -0.001467 0.088450" />
            <mass value="0.366" />
            <inertia ixx="0.000945510" ixy="-0.000011196" ixz="0" iyy="0.000811306" iyz="-0.000011704" izz="0.000402389" />
        </inertial>
        <visual>
            <origin rpy="0 0 0" xyz="0 0 0" />
            <geometry>
                <mesh filename="package://robot_description/meshes/Link_6.STL" />
            </geometry>
            <material name="">
                <color rgba="1 1 1 1" />
            </material>
        </visual>
        <collision>
            <origin rpy="0 0 0" xyz="0 0 0" />
            <geometry>
                <mesh filename="package://robot_description/meshes/Link_6.STL" />
            </geometry>
        </collision>
    </link>
    <joint name="Joint1_6" type="revolute">
        <origin rpy="3.141592653589793 -1.5707963267948966 0" xyz="0.141 0 0" />
        <parent link="Link1_5" />
        <child link="Link1_6" />
        <axis xyz="0 0 1" />
        <dynamics damping="0.1" friction="0.8" />
        <limit effort="100" lower="-3.141592653589793" upper="3.141592653589793" velocity="10" />
    </joint>
    <joint name="Joint1_hand" type="fixed">
        <parent link="Link1_6" />
        <child link="Link1_robotiq_arg2f_base_link" />
        <origin rpy="0 0 0" xyz="0 0 0.0385" />
    </joint>
    <transmission name="Link1_finger_joint_trans">
        <type>transmission_interface/SimpleTransmission</type>
        <joint name="Link1_finger_joint">
            <hardwareInterface>hardware_interface/EffortJointInterface</hardwareInterface>
        </joint>
        <actuator name="Link1_finger_joint_motor">
            <mechanicalReduction>1</mechanicalReduction>
            <hardwareInterface>hardware_interface/EffortJointInterface</hardwareInterface>
        </actuator>
    </transmission>
    <!-- base link -->
    <link name="Link1_robotiq_arg2f_base_link">
        <inertial>
            <origin rpy="0 0 0" xyz="8.625E-08 -4.6583E-06 0.03145" />
            <mass value="0.22652" />
            <inertia ixx="0.00020005" ixy="-4.2442E-10" ixz="-2.9069E-10" iyy="0.00017832" iyz="-3.4402E-08" izz="0.00013478" />
        </inertial>
        <visual>
            <origin rpy="0 0 0" xyz="0 0 0" />
            <geometry>
                <mesh filename="package://robotiq_2f_85_gripper_visualization/meshes/visual/robotiq_arg2f_base_link.stl" />
            </geometry>
            <material name="">
                <color rgba="0.1 0.1 0.1 1" />
            </material>
        </visual>
        <collision>
            <origin rpy="0 0 0" xyz="0 0 0" />
            <!-- <geometry><sphere radius="0.04" /></geometry> -->
            <geometry>
                <mesh filename="package://robotiq_2f_85_gripper_visualization/meshes/collision/robotiq_arg2f_base_link.stl" />
            </geometry>
            <surface>
                <friction>
                    <torsional>
                        <coefficient>5.0</coefficient>
                        <surface_radius>0.01</surface_radius>
                        <use_patch_radius>false</use_patch_radius>
                    </torsional>
                </friction>
            </surface>
        </collision>
    </link>
    <link name="Link1_left_outer_knuckle">
        <inertial>
            <origin rpy="0 0 0" xyz="-0.000200000000003065 0.0199435877845359 0.0292245259211331" />
            <mass value="0.00853198276973456" />
            <inertia ixx="2.89328108496468E-06" ixy="-1.57935047237397E-19" ixz="-1.93980378593255E-19" iyy="1.86719750325683E-06" iyz="-1.21858577871576E-06" izz="1.21905238907251E-06" />
        </inertial>
        <visual>
            <origin rpy="0 0 0" xyz="0 0 0" />
            <geometry>
                <mesh filename="package://robotiq_2f_85_gripper_visualization/meshes/visual/robotiq_arg2f_85_outer_knuckle.dae" scale="0.001 0.001 0.001" />
            </geometry>
            <material name="">
                <color rgba="0.792156862745098 0.819607843137255 0.933333333333333 1" />
            </material>
        </visual>
        <collision>
            <origin rpy="0 0 0" xyz="0 0 0" />
            <geometry>
                <mesh filename="package://robotiq_2f_85_gripper_visualization/meshes/collision/robotiq_arg2f_85_outer_knuckle.dae" scale="0.001 0.001 0.001" />
            </geometry>
        </collision>
    </link>
    <link name="Link1_left_outer_finger">
        <inertial>
            <origin rpy="0 0 0" xyz="0.00030115855001899 0.0373907951953854 -0.0208027427000385" />
            <mass value="0.022614240507152" />
            <inertia ixx="1.52518312458174E-05" ixy="9.76583423954399E-10" ixz="-5.43838577022588E-10" iyy="6.17694243867776E-06" iyz="6.78636130740228E-06" izz="1.16494917907219E-05" />
        </inertial>
        <visual>
            <origin rpy="0 0 0" xyz="0 0 0" />
            <geometry>
                <mesh filename="package://robotiq_2f_85_gripper_visualization/meshes/visual/robotiq_arg2f_85_outer_finger.dae" scale="0.001 0.001 0.001" />
            </geometry>
            <material name="">
                <color rgba="0.1 0.1 0.1 1" />
            </material>
        </visual>
        <collision>
            <origin rpy="0 0 0" xyz="0 0 0" />
            <geometry>
                <mesh filename="package://robotiq_2f_85_gripper_visualization/meshes/collision/robotiq_arg2f_85_outer_finger.dae" scale="0.001 0.001 0.001" />
            </geometry>
        </collision>
    </link>
    <link name="Link1_left_inner_finger">
        <inertial>
            <origin rpy="0 0 0" xyz="0.000299999999999317 0.0160078233491243 -0.0136945669206257" />
            <mass value="0.0104003125914103" />
            <inertia ixx="2.71909453810972E-06" ixy="1.35402465472579E-21" ixz="-7.1817349065269E-22" iyy="7.69100314106116E-07" iyz="6.74715432769696E-07" izz="2.30315190420171E-06" />
        </inertial>
        <visual>
            <origin rpy="0 0 0" xyz="0 0 0" />
            <geometry>
                <mesh filename="package://robotiq_2f_85_gripper_visualization/meshes/visual/robotiq_arg2f_85_inner_finger.dae" scale="0.001 0.001 0.001" />
            </geometry>
            <material name="">
                <color rgba="0.1 0.1 0.1 1" />
            </material>
        </visual>
        <collision>
            <origin rpy="0 0 0" xyz="0 0 0" />
            <geometry>
                <mesh filename="package://robotiq_2f_85_gripper_visualization/meshes/collision/robotiq_arg2f_85_inner_finger.dae" scale="0.001 0.001 0.001" />
            </geometry>
        </collision>
    </link>
    <link name="Link1_left_inner_finger_pad">
        <visual>
            <origin rpy="0 0 0" xyz="0 0 0" />
            <geometry>
                <box size="0.022 0.00635 0.0375" />
            </geometry>
            <material name="">
                <color rgba="0.9 0.9 0.9 1" />
            </material>
        </visual>
        <collision>
            <origin rpy="0 0 0" xyz="0 0 0" />
            <geometry>
                <box size="0.022 0.00635 0.0375" />
            </geometry>
            <material name="">
                <color rgba="0.9 0.0 0.0 1" />
            </material>
        </collision>
        <inertial>
            <mass value="0.1" />
            <origin xyz="0 0 0" rpy="0 0 0" />
            <inertia ixx="0.03" iyy="0.03" izz="0.03" ixy="0.0" ixz="0.0" iyz="0.0" />
        </inertial>
    </link>
    <link name="Link1_left_inner_knuckle">
        <inertial>
            <origin rpy="0 0 0" xyz="0.000123011831763771 0.0507850843201817 0.00103968640075166" />
            <mass value="0.0271177346495152" />
            <inertia ixx="2.61910379223783E-05" ixy="-2.43616858946494E-07" ixz="-6.37789906117123E-09" iyy="2.8270243746167E-06" iyz="-5.37200748039765E-07" izz="2.83695868220296E-05" />
        </inertial>
        <visual>
            <origin rpy="0 0 0" xyz="0 0 0" />
            <geometry>
                <mesh filename="package://robotiq_2f_85_gripper_visualization/meshes/visual/robotiq_arg2f_85_inner_knuckle.dae" scale="0.001 0.001 0.001" />
            </geometry>
            <material name="">
                <color rgba="0.1 0.1 0.1 1" />
            </material>
        </visual>
        <collision>
            <origin rpy="0 0 0" xyz="0 0 0" />
            <geometry>
                <mesh filename="package://robotiq_2f_85_gripper_visualization/meshes/collision/robotiq_arg2f_85_inner_knuckle.dae" scale="0.001 0.001 0.001" />
            </geometry>
        </collision>
    </link>
    <joint name="Link1_left_outer_finger_joint" type="fixed">
        <origin rpy="0 0 0" xyz="0 0.0315 -0.0041" />
        <parent link="Link1_left_outer_knuckle" />
        <child link="Link1_left_outer_finger" />
        <axis xyz="1 0 0" />
    </joint>
    <joint name="Link1_left_inner_knuckle_joint" type="revolute">
        <!-- <origin xyz="0 ${reflect * -0.0127} 0.06142" rpy="${pi / 2 + .725} 0 ${(reflect - 1) * pi / 2}" /> -->
        <origin rpy="0 0 3.141592653589793" xyz="0 -0.0127 0.06142" />
        <parent link="Link1_robotiq_arg2f_base_link" />
        <child link="Link1_left_inner_knuckle" />
        <axis xyz="1 0 0" />
        <limit effort="1000" lower="0" upper="0.8757" velocity="0.5" />
        <mimic joint="Link1_finger_joint" multiplier="1" offset="0" />
    </joint>
    <joint name="Link1_left_inner_finger_joint" type="revolute">
        <origin rpy="0 0 0" xyz="0 0.0061 0.0471" />
        <parent link="Link1_left_outer_finger" />
        <child link="Link1_left_inner_finger" />
        <axis xyz="1 0 0" />
        <limit effort="1000" lower="-0.8757" upper="0" velocity="0.5" />
        <mimic joint="Link1_finger_joint" multiplier="-1" offset="0" />
    </joint>
    <joint name="Link1_left_inner_finger_pad_joint" type="fixed">
        <origin rpy="0 0 0" xyz="0 -0.0220203446692936 0.03242" />
        <parent link="Link1_left_inner_finger" />
        <child link="Link1_left_inner_finger_pad" />
        <axis xyz="0 0 1" />
    </joint>
    <joint name="Link1_finger_joint" type="revolute">
        <origin rpy="0 0 3.141592653589793" xyz="0 -0.0306011 0.054904" />
        <parent link="Link1_robotiq_arg2f_base_link" />
        <child link="Link1_left_outer_knuckle" />
        <axis xyz="1 0 0" />
        <limit effort="1000" lower="0" upper="0.8" velocity="0.5" />
    </joint>
    <joint name="Link1_right_outer_finger_joint" type="fixed">
        <origin rpy="0 0 0" xyz="0 0.0315 -0.0041" />
        <parent link="Link1_right_outer_knuckle" />
        <child link="Link1_right_outer_finger" />
        <axis xyz="1 0 0" />
    </joint>
    <joint name="Link1_right_inner_knuckle_joint" type="revolute">
        <!-- <origin xyz="0 ${reflect * -0.0127} 0.06142" rpy="${pi / 2 + .725} 0 ${(reflect - 1) * pi / 2}" /> -->
        <origin rpy="0 0 0.0" xyz="0 0.0127 0.06142" />
        <parent link="Link1_robotiq_arg2f_base_link" />
        <child link="Link1_right_inner_knuckle" />
        <axis xyz="1 0 0" />
        <limit effort="1000" lower="0" upper="0.8757" velocity="0.5" />
        <mimic joint="Link1_finger_joint" multiplier="1" offset="0" />
    </joint>
    <joint name="Link1_right_inner_finger_joint" type="revolute">
        <origin rpy="0 0 0" xyz="0 0.0061 0.0471" />
        <parent link="Link1_right_outer_finger" />
        <child link="Link1_right_inner_finger" />
        <axis xyz="1 0 0" />
        <limit effort="1000" lower="-0.8757" upper="0" velocity="0.5" />
        <mimic joint="Link1_finger_joint" multiplier="-1" offset="0" />
    </joint>
    <joint name="Link1_right_inner_finger_pad_joint" type="fixed">
        <origin rpy="0 0 0" xyz="0 -0.0220203446692936 0.03242" />
        <parent link="Link1_right_inner_finger" />
        <child link="Link1_right_inner_finger_pad" />
        <axis xyz="0 0 1" />
    </joint>
    <link name="Link1_right_outer_knuckle">
        <inertial>
            <origin rpy="0 0 0" xyz="-0.000200000000003065 0.0199435877845359 0.0292245259211331" />
            <mass value="0.00853198276973456" />
            <inertia ixx="2.89328108496468E-06" ixy="-1.57935047237397E-19" ixz="-1.93980378593255E-19" iyy="1.86719750325683E-06" iyz="-1.21858577871576E-06" izz="1.21905238907251E-06" />
        </inertial>
        <visual>
            <origin rpy="0 0 0" xyz="0 0 0" />
            <geometry>
                <mesh filename="package://robotiq_2f_85_gripper_visualization/meshes/visual/robotiq_arg2f_85_outer_knuckle.dae" scale="0.001 0.001 0.001" />
            </geometry>
            <material name="">
                <color rgba="0.792156862745098 0.819607843137255 0.933333333333333 1" />
            </material>
        </visual>
        <collision>
            <origin rpy="0 0 0" xyz="0 0 0" />
            <geometry>
                <mesh filename="package://robotiq_2f_85_gripper_visualization/meshes/collision/robotiq_arg2f_85_outer_knuckle.dae" scale="0.001 0.001 0.001" />
            </geometry>
        </collision>
    </link>
    <link name="Link1_right_outer_finger">
        <inertial>
            <origin rpy="0 0 0" xyz="0.00030115855001899 0.0373907951953854 -0.0208027427000385" />
            <mass value="0.022614240507152" />
            <inertia ixx="1.52518312458174E-05" ixy="9.76583423954399E-10" ixz="-5.43838577022588E-10" iyy="6.17694243867776E-06" iyz="6.78636130740228E-06" izz="1.16494917907219E-05" />
        </inertial>
        <visual>
            <origin rpy="0 0 0" xyz="0 0 0" />
            <geometry>
                <mesh filename="package://robotiq_2f_85_gripper_visualization/meshes/visual/robotiq_arg2f_85_outer_finger.dae" scale="0.001 0.001 0.001" />
            </geometry>
            <material name="">
                <color rgba="0.1 0.1 0.1 1" />
            </material>
        </visual>
        <collision>
            <origin rpy="0 0 0" xyz="0 0 0" />
            <geometry>
                <mesh filename="package://robotiq_2f_85_gripper_visualization/meshes/collision/robotiq_arg2f_85_outer_finger.dae" scale="0.001 0.001 0.001" />
            </geometry>
        </collision>
    </link>
    <link name="Link1_right_inner_finger">
        <inertial>
            <origin rpy="0 0 0" xyz="0.000299999999999317 0.0160078233491243 -0.0136945669206257" />
            <mass value="0.0104003125914103" />
            <inertia ixx="2.71909453810972E-06" ixy="1.35402465472579E-21" ixz="-7.1817349065269E-22" iyy="7.69100314106116E-07" iyz="6.74715432769696E-07" izz="2.30315190420171E-06" />
        </inertial>
        <visual>
            <origin rpy="0 0 0" xyz="0 0 0" />
            <geometry>
                <mesh filename="package://robotiq_2f_85_gripper_visualization/meshes/visual/robotiq_arg2f_85_inner_finger.dae" scale="0.001 0.001 0.001" />
            </geometry>
            <material name="">
                <color rgba="0.1 0.1 0.1 1" />
            </material>
        </visual>
        <collision>
            <origin rpy="0 0 0" xyz="0 0 0" />
            <geometry>
                <mesh filename="package://robotiq_2f_85_gripper_visualization/meshes/collision/robotiq_arg2f_85_inner_finger.dae" scale="0.001 0.001 0.001" />
            </geometry>
        </collision>
    </link>
    <link name="Link1_right_inner_finger_pad">
        <visual>
            <origin rpy="0 0 0" xyz="0 0 0" />
            <geometry>
                <box size="0.022 0.00635 0.0375" />
            </geometry>
            <material name="">
                <color rgba="0.9 0.9 0.9 1" />
            </material>
        </visual>
        <collision>
            <origin rpy="0 0 0" xyz="0 0 0" />
            <geometry>
                <box size="0.022 0.00635 0.0375" />
            </geometry>
            <material name="">
                <color rgba="0.9 0.0 0.0 1" />
            </material>
        </collision>
        <inertial>
            <mass value="0.1" />
            <origin xyz="0 0 0" rpy="0 0 0" />
            <inertia ixx="0.03" iyy="0.03" izz="0.03" ixy="0.0" ixz="0.0" iyz="0.0" />
        </inertial>
    </link>
    <link name="Link1_right_inner_knuckle">
        <inertial>
            <origin rpy="0 0 0" xyz="0.000123011831763771 0.0507850843201817 0.00103968640075166" />
            <mass value="0.0271177346495152" />
            <inertia ixx="2.61910379223783E-05" ixy="-2.43616858946494E-07" ixz="-6.37789906117123E-09" iyy="2.8270243746167E-06" iyz="-5.37200748039765E-07" izz="2.83695868220296E-05" />
        </inertial>
        <visual>
            <origin rpy="0 0 0" xyz="0 0 0" />
            <geometry>
                <mesh filename="package://robotiq_2f_85_gripper_visualization/meshes/visual/robotiq_arg2f_85_inner_knuckle.dae" scale="0.001 0.001 0.001" />
            </geometry>
            <material name="">
                <color rgba="0.1 0.1 0.1 1" />
            </material>
        </visual>
        <collision>
            <origin rpy="0 0 0" xyz="0 0 0" />
            <geometry>
                <mesh filename="package://robotiq_2f_85_gripper_visualization/meshes/collision/robotiq_arg2f_85_inner_knuckle.dae" scale="0.001 0.001 0.001" />
            </geometry>
        </collision>
    </link>
    <joint name="Link1_right_finger_joint" type="revolute">
        <origin rpy="0 0 0" xyz="0 0.0306011 0.054904" />
        <parent link="Link1_robotiq_arg2f_base_link" />
        <child link="Link1_right_outer_knuckle" />
        <axis xyz="1 0 0" />
        <limit effort="1000" lower="0" upper="0.81" velocity="0.5" />
        <mimic joint="Link1_finger_joint" multiplier="1" offset="0" />
    </joint>
    <link name="Link2_0">
        <inertial>
            <origin rpy="0 0 0" xyz="0.085427 -0.025518 0" />
            <mass value="0.960" />
            <inertia ixx="0.000648473" ixy="-0.001018876" ixz="0.000012959" iyy="0.002674366" iyz="0" izz="0.003031056" />
        </inertial>
        <visual>
            <origin rpy="0 0 0" xyz="0 0 0" />
            <geometry>
                <mesh filename="package://robot_description/meshes/Link_0.STL" />
            </geometry>
            <material name="">
                <color rgba="0 1 1 1" />
            </material>
        </visual>
        <collision>
            <origin rpy="0 0 0" xyz="0 0 0" />
            <geometry>
                <mesh filename="package://robot_description/meshes/Link_0.STL" />
            </geometry>
        </collision>
    </link>
    <joint name="Joint2_0" type="revolute">
        <origin rpy="1.5707963267948966 0 2.356194490192345" xyz="-0.072125 0.072125 0.018" />
        <parent link="base_link" />
        <child link="Link2_0" />
        <axis xyz="0 0 1" />
        <dynamics damping="0.1" friction="0.8" />
        <limit effort="1000" lower="0" upper="1.5707963267948966" velocity="10" />
    </joint>
    <link name="Link2_1">
        <inertial>
            <origin rpy="0 0 0" xyz="0.052469 -0.009040 0.002060" />
            <mass value="0.914" />
            <inertia ixx="0.000671687" ixy="-0.000084224" ixz="-0.000107815" iyy="0.000786758" iyz="0.000017298" izz="0.000958254" />
        </inertial>
        <visual>
            <origin rpy="0 0 0" xyz="0 0 0" />
            <geometry>
                <mesh filename="package://robot_description/meshes/Link_1.STL" />
            </geometry>
            <material name="">
                <color rgba="1 1 1 1" />
            </material>
        </visual>
        <collision>
            <origin rpy="0 0 0" xyz="0 0 0" />
            <geometry>
                <mesh filename="package://robot_description/meshes/Link_1.STL" />
            </geometry>
        </collision>
    </link>
    <joint name="Joint2_1" type="revolute">
        <origin rpy="-1.5707963267948966 0 0" xyz="0.12 -0.117 0" />
        <parent link="Link2_0" />
        <child link="Link2_1" />
        <axis xyz="0 0 1" />
        <dynamics damping="0.1" friction="0.8" />
        <limit effort="300" lower="-2.356194490192345" upper="4.71238898038469" velocity="10" />
    </joint>
    <link name="Link2_2">
        <inertial>
            <origin rpy="0 0 0" xyz="0.273270 0.000006 0.007530" />
            <mass value="1.144" />
            <inertia ixx="0.000909959" ixy="0" ixz="0.000569994" iyy="0.018834040" iyz="0" izz="0.018336908" />
        </inertial>
        <visual>
            <origin rpy="0 0 0" xyz="0 0 0" />
            <geometry>
                <mesh filename="package://robot_description/meshes/Link_2.STL" />
            </geometry>
            <material name="">
                <color rgba="1 1 1 1" />
            </material>
        </visual>
        <collision>
            <origin rpy="0 0 0" xyz="0 0 0" />
            <geometry>
                <mesh filename="package://robot_description/meshes/Link_2.STL" />
            </geometry>
        </collision>
    </link>
    <joint name="Joint2_2" type="revolute">
        <origin rpy="1.5707963267948966 0 0" xyz="0.0625 -0.0025 0" />
        <parent link="Link2_1" />
        <child link="Link2_2" />
        <axis xyz="0 0 1" />
        <dynamics damping="0.1" friction="0.8" />
        <limit effort="300" lower="-2.0943951023931953" upper="1.5707963267948966" velocity="10" />
    </joint>
    <link name="Link2_3">
        <inertial>
            <origin rpy="0 0 0" xyz="0.081336 -0.0003 -0.000693" />
            <mass value="0.395" />
            <inertia ixx="0.000576423" ixy="0" ixz="0.000031283" iyy="0.001662107" iyz="0" izz="0.001334389" />
        </inertial>
        <visual>
            <origin rpy="0 0 0" xyz="0 0 0" />
            <geometry>
                <mesh filename="package://robot_description/meshes/Link_3.STL" />
            </geometry>
            <material name="">
                <color rgba="1 1 1 1" />
            </material>
        </visual>
        <collision>
            <origin rpy="0 0 0" xyz="0 0 0" />
            <geometry>
                <mesh filename="package://robot_description/meshes/Link_3.STL" />
            </geometry>
        </collision>
    </link>
    <joint name="Joint2_3" type="revolute">
        <origin rpy="-3.141592653589793 0 0" xyz="0.35 0.0002 0" />
        <parent link="Link2_2" />
        <child link="Link2_3" />
        <axis xyz="0 0 1" />
        <dynamics damping="0.1" friction="0.8" />
        <limit effort="300" lower="-2.530727415391778" upper="2.530727415391778" velocity="10" />
    </joint>
    <link name="Link2_4">
        <inertial>
            <origin rpy="0 0 0" xyz="0.005438 0.000120 0.134002" />
            <mass value="0.376" />
            <inertia ixx="0.0001484574" ixy="0" ixz="0.000099045" iyy="0.001658464" iyz="-0.000002871" izz="0.000360737" />
        </inertial>
        <visual>
            <origin rpy="0 0 0" xyz="0 0 0" />
            <geometry>
                <mesh filename="package://robot_description/meshes/Link_4.STL" />
            </geometry>
            <material name="">
                <color rgba="1 1 1 1" />
            </material>
        </visual>
        <collision>
            <origin rpy="0 0 0" xyz="0 0 0" />
            <geometry>
                <mesh filename="package://robot_description/meshes/Link_4.STL" />
            </geometry>
        </collision>
    </link>
    <joint name="Joint2_4" type="revolute">
        <origin rpy="0 -1.5707963267948966 -3.141592653589793" xyz="0.1745 0 0" />
        <parent link="Link2_3" />
        <child link="Link2_4" />
        <axis xyz="0 0 1" />
        <dynamics damping="0.1" friction="0.8" />
        <limit effort="100" lower="-3.141592653589793" upper="3.141592653589793" velocity="10" />
    </joint>
    <link name="Link2_5">
        <inertial>
            <origin rpy="0 0 0" xyz="0.058277 0 -0.001068" />
            <mass value="0.327" />
            <inertia ixx="0.000412080" ixy="0" ixz="0.000002889" iyy="0.000943104" iyz="0" izz="0.000708641" />
        </inertial>
        <visual>
            <origin rpy="0 0 0" xyz="0 0 0" />
            <geometry>
                <mesh filename="package://robot_description/meshes/Link_5.STL" />
            </geometry>
            <material name="">
                <color rgba="1 1 1 1" />
            </material>
        </visual>
        <collision>
            <origin rpy="0 0 0" xyz="0 0 0" />
            <geometry>
                <mesh filename="package://robot_description/meshes/Link_5.STL" />
            </geometry>
        </collision>
    </link>
    <joint name="Joint2_5" type="revolute">
        <origin rpy="3.141592653589793 -1.5707963267948966 0" xyz="0 0 0.1795" />
        <parent link="Link2_4" />
        <child link="Link2_5" />
        <axis xyz="0 0 1" />
        <dynamics damping="0.1" friction="0.8" />
        <limit effort="100" lower="-1.9198621771937623" upper="1.9198621771937623" velocity="10" />
    </joint>
    <link name="Link2_6">
        <inertial>
            <origin rpy="0 0 0" xyz="-0.000076 -0.001467 0.088450" />
            <mass value="0.366" />
            <inertia ixx="0.000945510" ixy="-0.000011196" ixz="0" iyy="0.000811306" iyz="-0.000011704" izz="0.000402389" />
        </inertial>
        <visual>
            <origin rpy="0 0 0" xyz="0 0 0" />
            <geometry>
                <mesh filename="package://robot_description/meshes/Link_6.STL" />
            </geometry>
            <material name="">
                <color rgba="1 1 1 1" />
            </material>
        </visual>
        <collision>
            <origin rpy="0 0 0" xyz="0 0 0" />
            <geometry>
                <mesh filename="package://robot_description/meshes/Link_6.STL" />
            </geometry>
        </collision>
    </link>
    <joint name="Joint2_6" type="revolute">
        <origin rpy="3.141592653589793 -1.5707963267948966 0" xyz="0.141 0 0" />
        <parent link="Link2_5" />
        <child link="Link2_6" />
        <axis xyz="0 0 1" />
        <dynamics damping="0.1" friction="0.8" />
        <limit effort="100" lower="-3.141592653589793" upper="3.141592653589793" velocity="10" />
    </joint>
    <joint name="Joint2_hand" type="fixed">
        <parent link="Link2_6" />
        <child link="Link2_robotiq_arg2f_base_link" />
        <origin rpy="0 0 0" xyz="0 0 0.0385" />
    </joint>
    <transmission name="Link2_finger_joint_trans">
        <type>transmission_interface/SimpleTransmission</type>
        <joint name="Link2_finger_joint">
            <hardwareInterface>hardware_interface/EffortJointInterface</hardwareInterface>
        </joint>
        <actuator name="Link2_finger_joint_motor">
            <mechanicalReduction>1</mechanicalReduction>
            <hardwareInterface>hardware_interface/EffortJointInterface</hardwareInterface>
        </actuator>
    </transmission>
    <!-- base link -->
    <link name="Link2_robotiq_arg2f_base_link">
        <inertial>
            <origin rpy="0 0 0" xyz="8.625E-08 -4.6583E-06 0.03145" />
            <mass value="0.22652" />
            <inertia ixx="0.00020005" ixy="-4.2442E-10" ixz="-2.9069E-10" iyy="0.00017832" iyz="-3.4402E-08" izz="0.00013478" />
        </inertial>
        <visual>
            <origin rpy="0 0 0" xyz="0 0 0" />
            <geometry>
                <mesh filename="package://robotiq_2f_85_gripper_visualization/meshes/visual/robotiq_arg2f_base_link.stl" />
            </geometry>
            <material name="">
                <color rgba="0.1 0.1 0.1 1" />
            </material>
        </visual>
        <collision>
            <origin rpy="0 0 0" xyz="0 0 0" />
            <!-- <geometry><sphere radius="0.04" /></geometry> -->
            <geometry>
                <mesh filename="package://robotiq_2f_85_gripper_visualization/meshes/collision/robotiq_arg2f_base_link.stl" />
            </geometry>
            <surface>
                <friction>
                    <torsional>
                        <coefficient>5.0</coefficient>
                        <surface_radius>0.01</surface_radius>
                        <use_patch_radius>false</use_patch_radius>
                    </torsional>
                </friction>
            </surface>
        </collision>
    </link>
    <link name="Link2_left_outer_knuckle">
        <inertial>
            <origin rpy="0 0 0" xyz="-0.000200000000003065 0.0199435877845359 0.0292245259211331" />
            <mass value="0.00853198276973456" />
            <inertia ixx="2.89328108496468E-06" ixy="-1.57935047237397E-19" ixz="-1.93980378593255E-19" iyy="1.86719750325683E-06" iyz="-1.21858577871576E-06" izz="1.21905238907251E-06" />
        </inertial>
        <visual>
            <origin rpy="0 0 0" xyz="0 0 0" />
            <geometry>
                <mesh filename="package://robotiq_2f_85_gripper_visualization/meshes/visual/robotiq_arg2f_85_outer_knuckle.dae" scale="0.001 0.001 0.001" />
            </geometry>
            <material name="">
                <color rgba="0.792156862745098 0.819607843137255 0.933333333333333 1" />
            </material>
        </visual>
        <collision>
            <origin rpy="0 0 0" xyz="0 0 0" />
            <geometry>
                <mesh filename="package://robotiq_2f_85_gripper_visualization/meshes/collision/robotiq_arg2f_85_outer_knuckle.dae" scale="0.001 0.001 0.001" />
            </geometry>
        </collision>
    </link>
    <link name="Link2_left_outer_finger">
        <inertial>
            <origin rpy="0 0 0" xyz="0.00030115855001899 0.0373907951953854 -0.0208027427000385" />
            <mass value="0.022614240507152" />
            <inertia ixx="1.52518312458174E-05" ixy="9.76583423954399E-10" ixz="-5.43838577022588E-10" iyy="6.17694243867776E-06" iyz="6.78636130740228E-06" izz="1.16494917907219E-05" />
        </inertial>
        <visual>
            <origin rpy="0 0 0" xyz="0 0 0" />
            <geometry>
                <mesh filename="package://robotiq_2f_85_gripper_visualization/meshes/visual/robotiq_arg2f_85_outer_finger.dae" scale="0.001 0.001 0.001" />
            </geometry>
            <material name="">
                <color rgba="0.1 0.1 0.1 1" />
            </material>
        </visual>
        <collision>
            <origin rpy="0 0 0" xyz="0 0 0" />
            <geometry>
                <mesh filename="package://robotiq_2f_85_gripper_visualization/meshes/collision/robotiq_arg2f_85_outer_finger.dae" scale="0.001 0.001 0.001" />
            </geometry>
        </collision>
    </link>
    <link name="Link2_left_inner_finger">
        <inertial>
            <origin rpy="0 0 0" xyz="0.000299999999999317 0.0160078233491243 -0.0136945669206257" />
            <mass value="0.0104003125914103" />
            <inertia ixx="2.71909453810972E-06" ixy="1.35402465472579E-21" ixz="-7.1817349065269E-22" iyy="7.69100314106116E-07" iyz="6.74715432769696E-07" izz="2.30315190420171E-06" />
        </inertial>
        <visual>
            <origin rpy="0 0 0" xyz="0 0 0" />
            <geometry>
                <mesh filename="package://robotiq_2f_85_gripper_visualization/meshes/visual/robotiq_arg2f_85_inner_finger.dae" scale="0.001 0.001 0.001" />
            </geometry>
            <material name="">
                <color rgba="0.1 0.1 0.1 1" />
            </material>
        </visual>
        <collision>
            <origin rpy="0 0 0" xyz="0 0 0" />
            <geometry>
                <mesh filename="package://robotiq_2f_85_gripper_visualization/meshes/collision/robotiq_arg2f_85_inner_finger.dae" scale="0.001 0.001 0.001" />
            </geometry>
        </collision>
    </link>
    <link name="Link2_left_inner_finger_pad">
        <visual>
            <origin rpy="0 0 0" xyz="0 0 0" />
            <geometry>
                <box size="0.022 0.00635 0.0375" />
            </geometry>
            <material name="">
                <color rgba="0.9 0.9 0.9 1" />
            </material>
        </visual>
        <collision>
            <origin rpy="0 0 0" xyz="0 0 0" />
            <geometry>
                <box size="0.022 0.00635 0.0375" />
            </geometry>
            <material name="">
                <color rgba="0.9 0.0 0.0 1" />
            </material>
        </collision>
        <inertial>
            <mass value="0.1" />
            <origin xyz="0 0 0" rpy="0 0 0" />
            <inertia ixx="0.03" iyy="0.03" izz="0.03" ixy="0.0" ixz="0.0" iyz="0.0" />
        </inertial>
    </link>
    <link name="Link2_left_inner_knuckle">
        <inertial>
            <origin rpy="0 0 0" xyz="0.000123011831763771 0.0507850843201817 0.00103968640075166" />
            <mass value="0.0271177346495152" />
            <inertia ixx="2.61910379223783E-05" ixy="-2.43616858946494E-07" ixz="-6.37789906117123E-09" iyy="2.8270243746167E-06" iyz="-5.37200748039765E-07" izz="2.83695868220296E-05" />
        </inertial>
        <visual>
            <origin rpy="0 0 0" xyz="0 0 0" />
            <geometry>
                <mesh filename="package://robotiq_2f_85_gripper_visualization/meshes/visual/robotiq_arg2f_85_inner_knuckle.dae" scale="0.001 0.001 0.001" />
            </geometry>
            <material name="">
                <color rgba="0.1 0.1 0.1 1" />
            </material>
        </visual>
        <collision>
            <origin rpy="0 0 0" xyz="0 0 0" />
            <geometry>
                <mesh filename="package://robotiq_2f_85_gripper_visualization/meshes/collision/robotiq_arg2f_85_inner_knuckle.dae" scale="0.001 0.001 0.001" />
            </geometry>
        </collision>
    </link>
    <joint name="Link2_left_outer_finger_joint" type="fixed">
        <origin rpy="0 0 0" xyz="0 0.0315 -0.0041" />
        <parent link="Link2_left_outer_knuckle" />
        <child link="Link2_left_outer_finger" />
        <axis xyz="1 0 0" />
    </joint>
    <joint name="Link2_left_inner_knuckle_joint" type="revolute">
        <!-- <origin xyz="0 ${reflect * -0.0127} 0.06142" rpy="${pi / 2 + .725} 0 ${(reflect - 1) * pi / 2}" /> -->
        <origin rpy="0 0 3.141592653589793" xyz="0 -0.0127 0.06142" />
        <parent link="Link2_robotiq_arg2f_base_link" />
        <child link="Link2_left_inner_knuckle" />
        <axis xyz="1 0 0" />
        <limit effort="1000" lower="0" upper="0.8757" velocity="0.5" />
        <mimic joint="Link2_finger_joint" multiplier="1" offset="0" />
    </joint>
    <joint name="Link2_left_inner_finger_joint" type="revolute">
        <origin rpy="0 0 0" xyz="0 0.0061 0.0471" />
        <parent link="Link2_left_outer_finger" />
        <child link="Link2_left_inner_finger" />
        <axis xyz="1 0 0" />
        <limit effort="1000" lower="-0.8757" upper="0" velocity="0.5" />
        <mimic joint="Link2_finger_joint" multiplier="-1" offset="0" />
    </joint>
    <joint name="Link2_left_inner_finger_pad_joint" type="fixed">
        <origin rpy="0 0 0" xyz="0 -0.0220203446692936 0.03242" />
        <parent link="Link2_left_inner_finger" />
        <child link="Link2_left_inner_finger_pad" />
        <axis xyz="0 0 1" />
    </joint>
    <joint name="Link2_finger_joint" type="revolute">
        <origin rpy="0 0 3.141592653589793" xyz="0 -0.0306011 0.054904" />
        <parent link="Link2_robotiq_arg2f_base_link" />
        <child link="Link2_left_outer_knuckle" />
        <axis xyz="1 0 0" />
        <limit effort="1000" lower="0" upper="0.8" velocity="0.5" />
    </joint>
    <joint name="Link2_right_outer_finger_joint" type="fixed">
        <origin rpy="0 0 0" xyz="0 0.0315 -0.0041" />
        <parent link="Link2_right_outer_knuckle" />
        <child link="Link2_right_outer_finger" />
        <axis xyz="1 0 0" />
    </joint>
    <joint name="Link2_right_inner_knuckle_joint" type="revolute">
        <!-- <origin xyz="0 ${reflect * -0.0127} 0.06142" rpy="${pi / 2 + .725} 0 ${(reflect - 1) * pi / 2}" /> -->
        <origin rpy="0 0 0.0" xyz="0 0.0127 0.06142" />
        <parent link="Link2_robotiq_arg2f_base_link" />
        <child link="Link2_right_inner_knuckle" />
        <axis xyz="1 0 0" />
        <limit effort="1000" lower="0" upper="0.8757" velocity="0.5" />
        <mimic joint="Link2_finger_joint" multiplier="1" offset="0" />
    </joint>
    <joint name="Link2_right_inner_finger_joint" type="revolute">
        <origin rpy="0 0 0" xyz="0 0.0061 0.0471" />
        <parent link="Link2_right_outer_finger" />
        <child link="Link2_right_inner_finger" />
        <axis xyz="1 0 0" />
        <limit effort="1000" lower="-0.8757" upper="0" velocity="0.5" />
        <mimic joint="Link2_finger_joint" multiplier="-1" offset="0" />
    </joint>
    <joint name="Link2_right_inner_finger_pad_joint" type="fixed">
        <origin rpy="0 0 0" xyz="0 -0.0220203446692936 0.03242" />
        <parent link="Link2_right_inner_finger" />
        <child link="Link2_right_inner_finger_pad" />
        <axis xyz="0 0 1" />
    </joint>
    <link name="Link2_right_outer_knuckle">
        <inertial>
            <origin rpy="0 0 0" xyz="-0.000200000000003065 0.0199435877845359 0.0292245259211331" />
            <mass value="0.00853198276973456" />
            <inertia ixx="2.89328108496468E-06" ixy="-1.57935047237397E-19" ixz="-1.93980378593255E-19" iyy="1.86719750325683E-06" iyz="-1.21858577871576E-06" izz="1.21905238907251E-06" />
        </inertial>
        <visual>
            <origin rpy="0 0 0" xyz="0 0 0" />
            <geometry>
                <mesh filename="package://robotiq_2f_85_gripper_visualization/meshes/visual/robotiq_arg2f_85_outer_knuckle.dae" scale="0.001 0.001 0.001" />
            </geometry>
            <material name="">
                <color rgba="0.792156862745098 0.819607843137255 0.933333333333333 1" />
            </material>
        </visual>
        <collision>
            <origin rpy="0 0 0" xyz="0 0 0" />
            <geometry>
                <mesh filename="package://robotiq_2f_85_gripper_visualization/meshes/collision/robotiq_arg2f_85_outer_knuckle.dae" scale="0.001 0.001 0.001" />
            </geometry>
        </collision>
    </link>
    <link name="Link2_right_outer_finger">
        <inertial>
            <origin rpy="0 0 0" xyz="0.00030115855001899 0.0373907951953854 -0.0208027427000385" />
            <mass value="0.022614240507152" />
            <inertia ixx="1.52518312458174E-05" ixy="9.76583423954399E-10" ixz="-5.43838577022588E-10" iyy="6.17694243867776E-06" iyz="6.78636130740228E-06" izz="1.16494917907219E-05" />
        </inertial>
        <visual>
            <origin rpy="0 0 0" xyz="0 0 0" />
            <geometry>
                <mesh filename="package://robotiq_2f_85_gripper_visualization/meshes/visual/robotiq_arg2f_85_outer_finger.dae" scale="0.001 0.001 0.001" />
            </geometry>
            <material name="">
                <color rgba="0.1 0.1 0.1 1" />
            </material>
        </visual>
        <collision>
            <origin rpy="0 0 0" xyz="0 0 0" />
            <geometry>
                <mesh filename="package://robotiq_2f_85_gripper_visualization/meshes/collision/robotiq_arg2f_85_outer_finger.dae" scale="0.001 0.001 0.001" />
            </geometry>
        </collision>
    </link>
    <link name="Link2_right_inner_finger">
        <inertial>
            <origin rpy="0 0 0" xyz="0.000299999999999317 0.0160078233491243 -0.0136945669206257" />
            <mass value="0.0104003125914103" />
            <inertia ixx="2.71909453810972E-06" ixy="1.35402465472579E-21" ixz="-7.1817349065269E-22" iyy="7.69100314106116E-07" iyz="6.74715432769696E-07" izz="2.30315190420171E-06" />
        </inertial>
        <visual>
            <origin rpy="0 0 0" xyz="0 0 0" />
            <geometry>
                <mesh filename="package://robotiq_2f_85_gripper_visualization/meshes/visual/robotiq_arg2f_85_inner_finger.dae" scale="0.001 0.001 0.001" />
            </geometry>
            <material name="">
                <color rgba="0.1 0.1 0.1 1" />
            </material>
        </visual>
        <collision>
            <origin rpy="0 0 0" xyz="0 0 0" />
            <geometry>
                <mesh filename="package://robotiq_2f_85_gripper_visualization/meshes/collision/robotiq_arg2f_85_inner_finger.dae" scale="0.001 0.001 0.001" />
            </geometry>
        </collision>
    </link>
    <link name="Link2_right_inner_finger_pad">
        <visual>
            <origin rpy="0 0 0" xyz="0 0 0" />
            <geometry>
                <box size="0.022 0.00635 0.0375" />
            </geometry>
            <material name="">
                <color rgba="0.9 0.9 0.9 1" />
            </material>
        </visual>
        <collision>
            <origin rpy="0 0 0" xyz="0 0 0" />
            <geometry>
                <box size="0.022 0.00635 0.0375" />
            </geometry>
            <material name="">
                <color rgba="0.9 0.0 0.0 1" />
            </material>
        </collision>
        <inertial>
            <mass value="0.1" />
            <origin xyz="0 0 0" rpy="0 0 0" />
            <inertia ixx="0.03" iyy="0.03" izz="0.03" ixy="0.0" ixz="0.0" iyz="0.0" />
        </inertial>
    </link>
    <link name="Link2_right_inner_knuckle">
        <inertial>
            <origin rpy="0 0 0" xyz="0.000123011831763771 0.0507850843201817 0.00103968640075166" />
            <mass value="0.0271177346495152" />
            <inertia ixx="2.61910379223783E-05" ixy="-2.43616858946494E-07" ixz="-6.37789906117123E-09" iyy="2.8270243746167E-06" iyz="-5.37200748039765E-07" izz="2.83695868220296E-05" />
        </inertial>
        <visual>
            <origin rpy="0 0 0" xyz="0 0 0" />
            <geometry>
                <mesh filename="package://robotiq_2f_85_gripper_visualization/meshes/visual/robotiq_arg2f_85_inner_knuckle.dae" scale="0.001 0.001 0.001" />
            </geometry>
            <material name="">
                <color rgba="0.1 0.1 0.1 1" />
            </material>
        </visual>
        <collision>
            <origin rpy="0 0 0" xyz="0 0 0" />
            <geometry>
                <mesh filename="package://robotiq_2f_85_gripper_visualization/meshes/collision/robotiq_arg2f_85_inner_knuckle.dae" scale="0.001 0.001 0.001" />
            </geometry>
        </collision>
    </link>
    <joint name="Link2_right_finger_joint" type="revolute">
        <origin rpy="0 0 0" xyz="0 0.0306011 0.054904" />
        <parent link="Link2_robotiq_arg2f_base_link" />
        <child link="Link2_right_outer_knuckle" />
        <axis xyz="1 0 0" />
        <limit effort="1000" lower="0" upper="0.81" velocity="0.5" />
        <mimic joint="Link2_finger_joint" multiplier="1" offset="0" />
    </joint>
    <link name="Link3_0">
        <inertial>
            <origin rpy="0 0 0" xyz="0.085427 -0.025518 0" />
            <mass value="0.960" />
            <inertia ixx="0.000648473" ixy="-0.001018876" ixz="0.000012959" iyy="0.002674366" iyz="0" izz="0.003031056" />
        </inertial>
        <visual>
            <origin rpy="0 0 0" xyz="0 0 0" />
            <geometry>
                <mesh filename="package://robot_description/meshes/Link_0.STL" />
            </geometry>
            <material name="">
                <color rgba="0 1 1 1" />
            </material>
        </visual>
        <collision>
            <origin rpy="0 0 0" xyz="0 0 0" />
            <geometry>
                <mesh filename="package://robot_description/meshes/Link_0.STL" />
            </geometry>
        </collision>
    </link>
    <joint name="Joint3_0" type="revolute">
        <origin rpy="1.5707963267948966 0 3.9269908169872414" xyz="-0.072125 -0.072125 0.018" />
        <parent link="base_link" />
        <child link="Link3_0" />
        <axis xyz="0 0 1" />
        <dynamics damping="0.1" friction="0.8" />
        <limit effort="1000" lower="0" upper="1.5707963267948966" velocity="10" />
    </joint>
    <link name="Link3_1">
        <inertial>
            <origin rpy="0 0 0" xyz="0.052469 -0.009040 0.002060" />
            <mass value="0.914" />
            <inertia ixx="0.000671687" ixy="-0.000084224" ixz="-0.000107815" iyy="0.000786758" iyz="0.000017298" izz="0.000958254" />
        </inertial>
        <visual>
            <origin rpy="0 0 0" xyz="0 0 0" />
            <geometry>
                <mesh filename="package://robot_description/meshes/Link_1.STL" />
            </geometry>
            <material name="">
                <color rgba="1 1 1 1" />
            </material>
        </visual>
        <collision>
            <origin rpy="0 0 0" xyz="0 0 0" />
            <geometry>
                <mesh filename="package://robot_description/meshes/Link_1.STL" />
            </geometry>
        </collision>
    </link>
    <joint name="Joint3_1" type="revolute">
        <origin rpy="-1.5707963267948966 0 0" xyz="0.12 -0.117 0" />
        <parent link="Link3_0" />
        <child link="Link3_1" />
        <axis xyz="0 0 1" />
        <dynamics damping="0.1" friction="0.8" />
        <limit effort="300" lower="-2.356194490192345" upper="4.71238898038469" velocity="10" />
    </joint>
    <link name="Link3_2">
        <inertial>
            <origin rpy="0 0 0" xyz="0.273270 0.000006 0.007530" />
            <mass value="1.144" />
            <inertia ixx="0.000909959" ixy="0" ixz="0.000569994" iyy="0.018834040" iyz="0" izz="0.018336908" />
        </inertial>
        <visual>
            <origin rpy="0 0 0" xyz="0 0 0" />
            <geometry>
                <mesh filename="package://robot_description/meshes/Link_2.STL" />
            </geometry>
            <material name="">
                <color rgba="1 1 1 1" />
            </material>
        </visual>
        <collision>
            <origin rpy="0 0 0" xyz="0 0 0" />
            <geometry>
                <mesh filename="package://robot_description/meshes/Link_2.STL" />
            </geometry>
        </collision>
    </link>
    <joint name="Joint3_2" type="revolute">
        <origin rpy="1.5707963267948966 0 0" xyz="0.0625 -0.0025 0" />
        <parent link="Link3_1" />
        <child link="Link3_2" />
        <axis xyz="0 0 1" />
        <dynamics damping="0.1" friction="0.8" />
        <limit effort="300" lower="-2.0943951023931953" upper="1.5707963267948966" velocity="10" />
    </joint>
    <link name="Link3_3">
        <inertial>
            <origin rpy="0 0 0" xyz="0.081336 -0.0003 -0.000693" />
            <mass value="0.395" />
            <inertia ixx="0.000576423" ixy="0" ixz="0.000031283" iyy="0.001662107" iyz="0" izz="0.001334389" />
        </inertial>
        <visual>
            <origin rpy="0 0 0" xyz="0 0 0" />
            <geometry>
                <mesh filename="package://robot_description/meshes/Link_3.STL" />
            </geometry>
            <material name="">
                <color rgba="1 1 1 1" />
            </material>
        </visual>
        <collision>
            <origin rpy="0 0 0" xyz="0 0 0" />
            <geometry>
                <mesh filename="package://robot_description/meshes/Link_3.STL" />
            </geometry>
        </collision>
    </link>
    <joint name="Joint3_3" type="revolute">
        <origin rpy="-3.141592653589793 0 0" xyz="0.35 0.0002 0" />
        <parent link="Link3_2" />
        <child link="Link3_3" />
        <axis xyz="0 0 1" />
        <dynamics damping="0.1" friction="0.8" />
        <limit effort="300" lower="-2.530727415391778" upper="2.530727415391778" velocity="10" />
    </joint>
    <link name="Link3_4">
        <inertial>
            <origin rpy="0 0 0" xyz="0.005438 0.000120 0.134002" />
            <mass value="0.376" />
            <inertia ixx="0.0001484574" ixy="0" ixz="0.000099045" iyy="0.001658464" iyz="-0.000002871" izz="0.000360737" />
        </inertial>
        <visual>
            <origin rpy="0 0 0" xyz="0 0 0" />
            <geometry>
                <mesh filename="package://robot_description/meshes/Link_4.STL" />
            </geometry>
            <material name="">
                <color rgba="1 1 1 1" />
            </material>
        </visual>
        <collision>
            <origin rpy="0 0 0" xyz="0 0 0" />
            <geometry>
                <mesh filename="package://robot_description/meshes/Link_4.STL" />
            </geometry>
        </collision>
    </link>
    <joint name="Joint3_4" type="revolute">
        <origin rpy="0 -1.5707963267948966 -3.141592653589793" xyz="0.1745 0 0" />
        <parent link="Link3_3" />
        <child link="Link3_4" />
        <axis xyz="0 0 1" />
        <dynamics damping="0.1" friction="0.8" />
        <limit effort="100" lower="-3.141592653589793" upper="3.141592653589793" velocity="10" />
    </joint>
    <link name="Link3_5">
        <inertial>
            <origin rpy="0 0 0" xyz="0.058277 0 -0.001068" />
            <mass value="0.327" />
            <inertia ixx="0.000412080" ixy="0" ixz="0.000002889" iyy="0.000943104" iyz="0" izz="0.000708641" />
        </inertial>
        <visual>
            <origin rpy="0 0 0" xyz="0 0 0" />
            <geometry>
                <mesh filename="package://robot_description/meshes/Link_5.STL" />
            </geometry>
            <material name="">
                <color rgba="1 1 1 1" />
            </material>
        </visual>
        <collision>
            <origin rpy="0 0 0" xyz="0 0 0" />
            <geometry>
                <mesh filename="package://robot_description/meshes/Link_5.STL" />
            </geometry>
        </collision>
    </link>
    <joint name="Joint3_5" type="revolute">
        <origin rpy="3.141592653589793 -1.5707963267948966 0" xyz="0 0 0.1795" />
        <parent link="Link3_4" />
        <child link="Link3_5" />
        <axis xyz="0 0 1" />
        <dynamics damping="0.1" friction="0.8" />
        <limit effort="100" lower="-1.9198621771937623" upper="1.9198621771937623" velocity="10" />
    </joint>
    <link name="Link3_6">
        <inertial>
            <origin rpy="0 0 0" xyz="-0.000076 -0.001467 0.088450" />
            <mass value="0.366" />
            <inertia ixx="0.000945510" ixy="-0.000011196" ixz="0" iyy="0.000811306" iyz="-0.000011704" izz="0.000402389" />
        </inertial>
        <visual>
            <origin rpy="0 0 0" xyz="0 0 0" />
            <geometry>
                <mesh filename="package://robot_description/meshes/Link_6.STL" />
            </geometry>
            <material name="">
                <color rgba="1 1 1 1" />
            </material>
        </visual>
        <collision>
            <origin rpy="0 0 0" xyz="0 0 0" />
            <geometry>
                <mesh filename="package://robot_description/meshes/Link_6.STL" />
            </geometry>
        </collision>
    </link>
    <joint name="Joint3_6" type="revolute">
        <origin rpy="3.141592653589793 -1.5707963267948966 0" xyz="0.141 0 0" />
        <parent link="Link3_5" />
        <child link="Link3_6" />
        <axis xyz="0 0 1" />
        <dynamics damping="0.1" friction="0.8" />
        <limit effort="100" lower="-3.141592653589793" upper="3.141592653589793" velocity="10" />
    </joint>
    <joint name="Joint3_hand" type="fixed">
        <parent link="Link3_6" />
        <child link="Link3_robotiq_arg2f_base_link" />
        <origin rpy="0 0 0" xyz="0 0 0.0385" />
    </joint>
    <transmission name="Link3_finger_joint_trans">
        <type>transmission_interface/SimpleTransmission</type>
        <joint name="Link3_finger_joint">
            <hardwareInterface>hardware_interface/EffortJointInterface</hardwareInterface>
        </joint>
        <actuator name="Link3_finger_joint_motor">
            <mechanicalReduction>1</mechanicalReduction>
            <hardwareInterface>hardware_interface/EffortJointInterface</hardwareInterface>
        </actuator>
    </transmission>
    <!-- base link -->
    <link name="Link3_robotiq_arg2f_base_link">
        <inertial>
            <origin rpy="0 0 0" xyz="8.625E-08 -4.6583E-06 0.03145" />
            <mass value="0.22652" />
            <inertia ixx="0.00020005" ixy="-4.2442E-10" ixz="-2.9069E-10" iyy="0.00017832" iyz="-3.4402E-08" izz="0.00013478" />
        </inertial>
        <visual>
            <origin rpy="0 0 0" xyz="0 0 0" />
            <geometry>
                <mesh filename="package://robotiq_2f_85_gripper_visualization/meshes/visual/robotiq_arg2f_base_link.stl" />
            </geometry>
            <material name="">
                <color rgba="0.1 0.1 0.1 1" />
            </material>
        </visual>
        <collision>
            <origin rpy="0 0 0" xyz="0 0 0" />
            <!-- <geometry><sphere radius="0.04" /></geometry> -->
            <geometry>
                <mesh filename="package://robotiq_2f_85_gripper_visualization/meshes/collision/robotiq_arg2f_base_link.stl" />
            </geometry>
            <surface>
                <friction>
                    <torsional>
                        <coefficient>5.0</coefficient>
                        <surface_radius>0.01</surface_radius>
                        <use_patch_radius>false</use_patch_radius>
                    </torsional>
                </friction>
            </surface>
        </collision>
    </link>
    <link name="Link3_left_outer_knuckle">
        <inertial>
            <origin rpy="0 0 0" xyz="-0.000200000000003065 0.0199435877845359 0.0292245259211331" />
            <mass value="0.00853198276973456" />
            <inertia ixx="2.89328108496468E-06" ixy="-1.57935047237397E-19" ixz="-1.93980378593255E-19" iyy="1.86719750325683E-06" iyz="-1.21858577871576E-06" izz="1.21905238907251E-06" />
        </inertial>
        <visual>
            <origin rpy="0 0 0" xyz="0 0 0" />
            <geometry>
                <mesh filename="package://robotiq_2f_85_gripper_visualization/meshes/visual/robotiq_arg2f_85_outer_knuckle.dae" scale="0.001 0.001 0.001" />
            </geometry>
            <material name="">
                <color rgba="0.792156862745098 0.819607843137255 0.933333333333333 1" />
            </material>
        </visual>
        <collision>
            <origin rpy="0 0 0" xyz="0 0 0" />
            <geometry>
                <mesh filename="package://robotiq_2f_85_gripper_visualization/meshes/collision/robotiq_arg2f_85_outer_knuckle.dae" scale="0.001 0.001 0.001" />
            </geometry>
        </collision>
    </link>
    <link name="Link3_left_outer_finger">
        <inertial>
            <origin rpy="0 0 0" xyz="0.00030115855001899 0.0373907951953854 -0.0208027427000385" />
            <mass value="0.022614240507152" />
            <inertia ixx="1.52518312458174E-05" ixy="9.76583423954399E-10" ixz="-5.43838577022588E-10" iyy="6.17694243867776E-06" iyz="6.78636130740228E-06" izz="1.16494917907219E-05" />
        </inertial>
        <visual>
            <origin rpy="0 0 0" xyz="0 0 0" />
            <geometry>
                <mesh filename="package://robotiq_2f_85_gripper_visualization/meshes/visual/robotiq_arg2f_85_outer_finger.dae" scale="0.001 0.001 0.001" />
            </geometry>
            <material name="">
                <color rgba="0.1 0.1 0.1 1" />
            </material>
        </visual>
        <collision>
            <origin rpy="0 0 0" xyz="0 0 0" />
            <geometry>
                <mesh filename="package://robotiq_2f_85_gripper_visualization/meshes/collision/robotiq_arg2f_85_outer_finger.dae" scale="0.001 0.001 0.001" />
            </geometry>
        </collision>
    </link>
    <link name="Link3_left_inner_finger">
        <inertial>
            <origin rpy="0 0 0" xyz="0.000299999999999317 0.0160078233491243 -0.0136945669206257" />
            <mass value="0.0104003125914103" />
            <inertia ixx="2.71909453810972E-06" ixy="1.35402465472579E-21" ixz="-7.1817349065269E-22" iyy="7.69100314106116E-07" iyz="6.74715432769696E-07" izz="2.30315190420171E-06" />
        </inertial>
        <visual>
            <origin rpy="0 0 0" xyz="0 0 0" />
            <geometry>
                <mesh filename="package://robotiq_2f_85_gripper_visualization/meshes/visual/robotiq_arg2f_85_inner_finger.dae" scale="0.001 0.001 0.001" />
            </geometry>
            <material name="">
                <color rgba="0.1 0.1 0.1 1" />
            </material>
        </visual>
        <collision>
            <origin rpy="0 0 0" xyz="0 0 0" />
            <geometry>
                <mesh filename="package://robotiq_2f_85_gripper_visualization/meshes/collision/robotiq_arg2f_85_inner_finger.dae" scale="0.001 0.001 0.001" />
            </geometry>
        </collision>
    </link>
    <link name="Link3_left_inner_finger_pad">
        <visual>
            <origin rpy="0 0 0" xyz="0 0 0" />
            <geometry>
                <box size="0.022 0.00635 0.0375" />
            </geometry>
            <material name="">
                <color rgba="0.9 0.9 0.9 1" />
            </material>
        </visual>
        <collision>
            <origin rpy="0 0 0" xyz="0 0 0" />
            <geometry>
                <box size="0.022 0.00635 0.0375" />
            </geometry>
            <material name="">
                <color rgba="0.9 0.0 0.0 1" />
            </material>
        </collision>
        <inertial>
            <mass value="0.1" />
            <origin xyz="0 0 0" rpy="0 0 0" />
            <inertia ixx="0.03" iyy="0.03" izz="0.03" ixy="0.0" ixz="0.0" iyz="0.0" />
        </inertial>
    </link>
    <link name="Link3_left_inner_knuckle">
        <inertial>
            <origin rpy="0 0 0" xyz="0.000123011831763771 0.0507850843201817 0.00103968640075166" />
            <mass value="0.0271177346495152" />
            <inertia ixx="2.61910379223783E-05" ixy="-2.43616858946494E-07" ixz="-6.37789906117123E-09" iyy="2.8270243746167E-06" iyz="-5.37200748039765E-07" izz="2.83695868220296E-05" />
        </inertial>
        <visual>
            <origin rpy="0 0 0" xyz="0 0 0" />
            <geometry>
                <mesh filename="package://robotiq_2f_85_gripper_visualization/meshes/visual/robotiq_arg2f_85_inner_knuckle.dae" scale="0.001 0.001 0.001" />
            </geometry>
            <material name="">
                <color rgba="0.1 0.1 0.1 1" />
            </material>
        </visual>
        <collision>
            <origin rpy="0 0 0" xyz="0 0 0" />
            <geometry>
                <mesh filename="package://robotiq_2f_85_gripper_visualization/meshes/collision/robotiq_arg2f_85_inner_knuckle.dae" scale="0.001 0.001 0.001" />
            </geometry>
        </collision>
    </link>
    <joint name="Link3_left_outer_finger_joint" type="fixed">
        <origin rpy="0 0 0" xyz="0 0.0315 -0.0041" />
        <parent link="Link3_left_outer_knuckle" />
        <child link="Link3_left_outer_finger" />
        <axis xyz="1 0 0" />
    </joint>
    <joint name="Link3_left_inner_knuckle_joint" type="revolute">
        <!-- <origin xyz="0 ${reflect * -0.0127} 0.06142" rpy="${pi / 2 + .725} 0 ${(reflect - 1) * pi / 2}" /> -->
        <origin rpy="0 0 3.141592653589793" xyz="0 -0.0127 0.06142" />
        <parent link="Link3_robotiq_arg2f_base_link" />
        <child link="Link3_left_inner_knuckle" />
        <axis xyz="1 0 0" />
        <limit effort="1000" lower="0" upper="0.8757" velocity="0.5" />
        <mimic joint="Link3_finger_joint" multiplier="1" offset="0" />
    </joint>
    <joint name="Link3_left_inner_finger_joint" type="revolute">
        <origin rpy="0 0 0" xyz="0 0.0061 0.0471" />
        <parent link="Link3_left_outer_finger" />
        <child link="Link3_left_inner_finger" />
        <axis xyz="1 0 0" />
        <limit effort="1000" lower="-0.8757" upper="0" velocity="0.5" />
        <mimic joint="Link3_finger_joint" multiplier="-1" offset="0" />
    </joint>
    <joint name="Link3_left_inner_finger_pad_joint" type="fixed">
        <origin rpy="0 0 0" xyz="0 -0.0220203446692936 0.03242" />
        <parent link="Link3_left_inner_finger" />
        <child link="Link3_left_inner_finger_pad" />
        <axis xyz="0 0 1" />
    </joint>
    <joint name="Link3_finger_joint" type="revolute">
        <origin rpy="0 0 3.141592653589793" xyz="0 -0.0306011 0.054904" />
        <parent link="Link3_robotiq_arg2f_base_link" />
        <child link="Link3_left_outer_knuckle" />
        <axis xyz="1 0 0" />
        <limit effort="1000" lower="0" upper="0.8" velocity="0.5" />
    </joint>
    <joint name="Link3_right_outer_finger_joint" type="fixed">
        <origin rpy="0 0 0" xyz="0 0.0315 -0.0041" />
        <parent link="Link3_right_outer_knuckle" />
        <child link="Link3_right_outer_finger" />
        <axis xyz="1 0 0" />
    </joint>
    <joint name="Link3_right_inner_knuckle_joint" type="revolute">
        <!-- <origin xyz="0 ${reflect * -0.0127} 0.06142" rpy="${pi / 2 + .725} 0 ${(reflect - 1) * pi / 2}" /> -->
        <origin rpy="0 0 0.0" xyz="0 0.0127 0.06142" />
        <parent link="Link3_robotiq_arg2f_base_link" />
        <child link="Link3_right_inner_knuckle" />
        <axis xyz="1 0 0" />
        <limit effort="1000" lower="0" upper="0.8757" velocity="0.5" />
        <mimic joint="Link3_finger_joint" multiplier="1" offset="0" />
    </joint>
    <joint name="Link3_right_inner_finger_joint" type="revolute">
        <origin rpy="0 0 0" xyz="0 0.0061 0.0471" />
        <parent link="Link3_right_outer_finger" />
        <child link="Link3_right_inner_finger" />
        <axis xyz="1 0 0" />
        <limit effort="1000" lower="-0.8757" upper="0" velocity="0.5" />
        <mimic joint="Link3_finger_joint" multiplier="-1" offset="0" />
    </joint>
    <joint name="Link3_right_inner_finger_pad_joint" type="fixed">
        <origin rpy="0 0 0" xyz="0 -0.0220203446692936 0.03242" />
        <parent link="Link3_right_inner_finger" />
        <child link="Link3_right_inner_finger_pad" />
        <axis xyz="0 0 1" />
    </joint>
    <link name="Link3_right_outer_knuckle">
        <inertial>
            <origin rpy="0 0 0" xyz="-0.000200000000003065 0.0199435877845359 0.0292245259211331" />
            <mass value="0.00853198276973456" />
            <inertia ixx="2.89328108496468E-06" ixy="-1.57935047237397E-19" ixz="-1.93980378593255E-19" iyy="1.86719750325683E-06" iyz="-1.21858577871576E-06" izz="1.21905238907251E-06" />
        </inertial>
        <visual>
            <origin rpy="0 0 0" xyz="0 0 0" />
            <geometry>
                <mesh filename="package://robotiq_2f_85_gripper_visualization/meshes/visual/robotiq_arg2f_85_outer_knuckle.dae" scale="0.001 0.001 0.001" />
            </geometry>
            <material name="">
                <color rgba="0.792156862745098 0.819607843137255 0.933333333333333 1" />
            </material>
        </visual>
        <collision>
            <origin rpy="0 0 0" xyz="0 0 0" />
            <geometry>
                <mesh filename="package://robotiq_2f_85_gripper_visualization/meshes/collision/robotiq_arg2f_85_outer_knuckle.dae" scale="0.001 0.001 0.001" />
            </geometry>
        </collision>
    </link>
    <link name="Link3_right_outer_finger">
        <inertial>
            <origin rpy="0 0 0" xyz="0.00030115855001899 0.0373907951953854 -0.0208027427000385" />
            <mass value="0.022614240507152" />
            <inertia ixx="1.52518312458174E-05" ixy="9.76583423954399E-10" ixz="-5.43838577022588E-10" iyy="6.17694243867776E-06" iyz="6.78636130740228E-06" izz="1.16494917907219E-05" />
        </inertial>
        <visual>
            <origin rpy="0 0 0" xyz="0 0 0" />
            <geometry>
                <mesh filename="package://robotiq_2f_85_gripper_visualization/meshes/visual/robotiq_arg2f_85_outer_finger.dae" scale="0.001 0.001 0.001" />
            </geometry>
            <material name="">
                <color rgba="0.1 0.1 0.1 1" />
            </material>
        </visual>
        <collision>
            <origin rpy="0 0 0" xyz="0 0 0" />
            <geometry>
                <mesh filename="package://robotiq_2f_85_gripper_visualization/meshes/collision/robotiq_arg2f_85_outer_finger.dae" scale="0.001 0.001 0.001" />
            </geometry>
        </collision>
    </link>
    <link name="Link3_right_inner_finger">
        <inertial>
            <origin rpy="0 0 0" xyz="0.000299999999999317 0.0160078233491243 -0.0136945669206257" />
            <mass value="0.0104003125914103" />
            <inertia ixx="2.71909453810972E-06" ixy="1.35402465472579E-21" ixz="-7.1817349065269E-22" iyy="7.69100314106116E-07" iyz="6.74715432769696E-07" izz="2.30315190420171E-06" />
        </inertial>
        <visual>
            <origin rpy="0 0 0" xyz="0 0 0" />
            <geometry>
                <mesh filename="package://robotiq_2f_85_gripper_visualization/meshes/visual/robotiq_arg2f_85_inner_finger.dae" scale="0.001 0.001 0.001" />
            </geometry>
            <material name="">
                <color rgba="0.1 0.1 0.1 1" />
            </material>
        </visual>
        <collision>
            <origin rpy="0 0 0" xyz="0 0 0" />
            <geometry>
                <mesh filename="package://robotiq_2f_85_gripper_visualization/meshes/collision/robotiq_arg2f_85_inner_finger.dae" scale="0.001 0.001 0.001" />
            </geometry>
        </collision>
    </link>
    <link name="Link3_right_inner_finger_pad">
        <visual>
            <origin rpy="0 0 0" xyz="0 0 0" />
            <geometry>
                <box size="0.022 0.00635 0.0375" />
            </geometry>
            <material name="">
                <color rgba="0.9 0.9 0.9 1" />
            </material>
        </visual>
        <collision>
            <origin rpy="0 0 0" xyz="0 0 0" />
            <geometry>
                <box size="0.022 0.00635 0.0375" />
            </geometry>
            <material name="">
                <color rgba="0.9 0.0 0.0 1" />
            </material>
        </collision>
        <inertial>
            <mass value="0.1" />
            <origin xyz="0 0 0" rpy="0 0 0" />
            <inertia ixx="0.03" iyy="0.03" izz="0.03" ixy="0.0" ixz="0.0" iyz="0.0" />
        </inertial>
    </link>
    <link name="Link3_right_inner_knuckle">
        <inertial>
            <origin rpy="0 0 0" xyz="0.000123011831763771 0.0507850843201817 0.00103968640075166" />
            <mass value="0.0271177346495152" />
            <inertia ixx="2.61910379223783E-05" ixy="-2.43616858946494E-07" ixz="-6.37789906117123E-09" iyy="2.8270243746167E-06" iyz="-5.37200748039765E-07" izz="2.83695868220296E-05" />
        </inertial>
        <visual>
            <origin rpy="0 0 0" xyz="0 0 0" />
            <geometry>
                <mesh filename="package://robotiq_2f_85_gripper_visualization/meshes/visual/robotiq_arg2f_85_inner_knuckle.dae" scale="0.001 0.001 0.001" />
            </geometry>
            <material name="">
                <color rgba="0.1 0.1 0.1 1" />
            </material>
        </visual>
        <collision>
            <origin rpy="0 0 0" xyz="0 0 0" />
            <geometry>
                <mesh filename="package://robotiq_2f_85_gripper_visualization/meshes/collision/robotiq_arg2f_85_inner_knuckle.dae" scale="0.001 0.001 0.001" />
            </geometry>
        </collision>
    </link>
    <joint name="Link3_right_finger_joint" type="revolute">
        <origin rpy="0 0 0" xyz="0 0.0306011 0.054904" />
        <parent link="Link3_robotiq_arg2f_base_link" />
        <child link="Link3_right_outer_knuckle" />
        <axis xyz="1 0 0" />
        <limit effort="1000" lower="0" upper="0.81" velocity="0.5" />
        <mimic joint="Link3_finger_joint" multiplier="1" offset="0" />
    </joint>
    <link name="Link4_0">
        <inertial>
            <origin rpy="0 0 0" xyz="0.085427 -0.025518 0" />
            <mass value="0.960" />
            <inertia ixx="0.000648473" ixy="-0.001018876" ixz="0.000012959" iyy="0.002674366" iyz="0" izz="0.003031056" />
        </inertial>
        <visual>
            <origin rpy="0 0 0" xyz="0 0 0" />
            <geometry>
                <mesh filename="package://robot_description/meshes/Link_0.STL" />
            </geometry>
            <material name="">
                <color rgba="0 1 1 1" />
            </material>
        </visual>
        <collision>
            <origin rpy="0 0 0" xyz="0 0 0" />
            <geometry>
                <mesh filename="package://robot_description/meshes/Link_0.STL" />
            </geometry>
        </collision>
    </link>
    <joint name="Joint4_0" type="revolute">
        <origin rpy="1.5707963267948966 0 5.497787143782138" xyz="0.072125 -0.072125 0.018" />
        <parent link="base_link" />
        <child link="Link4_0" />
        <axis xyz="0 0 1" />
        <dynamics damping="0.1" friction="0.8" />
        <limit effort="1000" lower="0" upper="1.5707963267948966" velocity="10" />
    </joint>
    <link name="Link4_1">
        <inertial>
            <origin rpy="0 0 0" xyz="0.052469 -0.009040 0.002060" />
            <mass value="0.914" />
            <inertia ixx="0.000671687" ixy="-0.000084224" ixz="-0.000107815" iyy="0.000786758" iyz="0.000017298" izz="0.000958254" />
        </inertial>
        <visual>
            <origin rpy="0 0 0" xyz="0 0 0" />
            <geometry>
                <mesh filename="package://robot_description/meshes/Link_1.STL" />
            </geometry>
            <material name="">
                <color rgba="1 1 1 1" />
            </material>
        </visual>
        <collision>
            <origin rpy="0 0 0" xyz="0 0 0" />
            <geometry>
                <mesh filename="package://robot_description/meshes/Link_1.STL" />
            </geometry>
        </collision>
    </link>
    <joint name="Joint4_1" type="revolute">
        <origin rpy="-1.5707963267948966 0 0" xyz="0.12 -0.117 0" />
        <parent link="Link4_0" />
        <child link="Link4_1" />
        <axis xyz="0 0 1" />
        <dynamics damping="0.1" friction="0.8" />
        <limit effort="300" lower="-2.356194490192345" upper="4.71238898038469" velocity="10" />
    </joint>
    <link name="Link4_2">
        <inertial>
            <origin rpy="0 0 0" xyz="0.273270 0.000006 0.007530" />
            <mass value="1.144" />
            <inertia ixx="0.000909959" ixy="0" ixz="0.000569994" iyy="0.018834040" iyz="0" izz="0.018336908" />
        </inertial>
        <visual>
            <origin rpy="0 0 0" xyz="0 0 0" />
            <geometry>
                <mesh filename="package://robot_description/meshes/Link_2.STL" />
            </geometry>
            <material name="">
                <color rgba="1 1 1 1" />
            </material>
        </visual>
        <collision>
            <origin rpy="0 0 0" xyz="0 0 0" />
            <geometry>
                <mesh filename="package://robot_description/meshes/Link_2.STL" />
            </geometry>
        </collision>
    </link>
    <joint name="Joint4_2" type="revolute">
        <origin rpy="1.5707963267948966 0 0" xyz="0.0625 -0.0025 0" />
        <parent link="Link4_1" />
        <child link="Link4_2" />
        <axis xyz="0 0 1" />
        <dynamics damping="0.1" friction="0.8" />
        <limit effort="300" lower="-2.0943951023931953" upper="1.5707963267948966" velocity="10" />
    </joint>
    <link name="Link4_3">
        <inertial>
            <origin rpy="0 0 0" xyz="0.081336 -0.0003 -0.000693" />
            <mass value="0.395" />
            <inertia ixx="0.000576423" ixy="0" ixz="0.000031283" iyy="0.001662107" iyz="0" izz="0.001334389" />
        </inertial>
        <visual>
            <origin rpy="0 0 0" xyz="0 0 0" />
            <geometry>
                <mesh filename="package://robot_description/meshes/Link_3.STL" />
            </geometry>
            <material name="">
                <color rgba="1 1 1 1" />
            </material>
        </visual>
        <collision>
            <origin rpy="0 0 0" xyz="0 0 0" />
            <geometry>
                <mesh filename="package://robot_description/meshes/Link_3.STL" />
            </geometry>
        </collision>
    </link>
    <joint name="Joint4_3" type="revolute">
        <origin rpy="-3.141592653589793 0 0" xyz="0.35 0.0002 0" />
        <parent link="Link4_2" />
        <child link="Link4_3" />
        <axis xyz="0 0 1" />
        <dynamics damping="0.1" friction="0.8" />
        <limit effort="300" lower="-2.530727415391778" upper="2.530727415391778" velocity="10" />
    </joint>
    <link name="Link4_4">
        <inertial>
            <origin rpy="0 0 0" xyz="0.005438 0.000120 0.134002" />
            <mass value="0.376" />
            <inertia ixx="0.0001484574" ixy="0" ixz="0.000099045" iyy="0.001658464" iyz="-0.000002871" izz="0.000360737" />
        </inertial>
        <visual>
            <origin rpy="0 0 0" xyz="0 0 0" />
            <geometry>
                <mesh filename="package://robot_description/meshes/Link_4.STL" />
            </geometry>
            <material name="">
                <color rgba="1 1 1 1" />
            </material>
        </visual>
        <collision>
            <origin rpy="0 0 0" xyz="0 0 0" />
            <geometry>
                <mesh filename="package://robot_description/meshes/Link_4.STL" />
            </geometry>
        </collision>
    </link>
    <joint name="Joint4_4" type="revolute">
        <origin rpy="0 -1.5707963267948966 -3.141592653589793" xyz="0.1745 0 0" />
        <parent link="Link4_3" />
        <child link="Link4_4" />
        <axis xyz="0 0 1" />
        <dynamics damping="0.1" friction="0.8" />
        <limit effort="100" lower="-3.141592653589793" upper="3.141592653589793" velocity="10" />
    </joint>
    <link name="Link4_5">
        <inertial>
            <origin rpy="0 0 0" xyz="0.058277 0 -0.001068" />
            <mass value="0.327" />
            <inertia ixx="0.000412080" ixy="0" ixz="0.000002889" iyy="0.000943104" iyz="0" izz="0.000708641" />
        </inertial>
        <visual>
            <origin rpy="0 0 0" xyz="0 0 0" />
            <geometry>
                <mesh filename="package://robot_description/meshes/Link_5.STL" />
            </geometry>
            <material name="">
                <color rgba="1 1 1 1" />
            </material>
        </visual>
        <collision>
            <origin rpy="0 0 0" xyz="0 0 0" />
            <geometry>
                <mesh filename="package://robot_description/meshes/Link_5.STL" />
            </geometry>
        </collision>
    </link>
    <joint name="Joint4_5" type="revolute">
        <origin rpy="3.141592653589793 -1.5707963267948966 0" xyz="0 0 0.1795" />
        <parent link="Link4_4" />
        <child link="Link4_5" />
        <axis xyz="0 0 1" />
        <dynamics damping="0.1" friction="0.8" />
        <limit effort="100" lower="-1.9198621771937623" upper="1.9198621771937623" velocity="10" />
    </joint>
    <link name="Link4_6">
        <inertial>
            <origin rpy="0 0 0" xyz="-0.000076 -0.001467 0.088450" />
            <mass value="0.366" />
            <inertia ixx="0.000945510" ixy="-0.000011196" ixz="0" iyy="0.000811306" iyz="-0.000011704" izz="0.000402389" />
        </inertial>
        <visual>
            <origin rpy="0 0 0" xyz="0 0 0" />
            <geometry>
                <mesh filename="package://robot_description/meshes/Link_6.STL" />
            </geometry>
            <material name="">
                <color rgba="1 1 1 1" />
            </material>
        </visual>
        <collision>
            <origin rpy="0 0 0" xyz="0 0 0" />
            <geometry>
                <mesh filename="package://robot_description/meshes/Link_6.STL" />
            </geometry>
        </collision>
    </link>
    <joint name="Joint4_6" type="revolute">
        <origin rpy="3.141592653589793 -1.5707963267948966 0" xyz="0.141 0 0" />
        <parent link="Link4_5" />
        <child link="Link4_6" />
        <axis xyz="0 0 1" />
        <dynamics damping="0.1" friction="0.8" />
        <limit effort="100" lower="-3.141592653589793" upper="3.141592653589793" velocity="10" />
    </joint>
    <joint name="Joint4_hand" type="fixed">
        <parent link="Link4_6" />
        <child link="Link4_robotiq_arg2f_base_link" />
        <origin rpy="0 0 0" xyz="0 0 0.0385" />
    </joint>
    <transmission name="Link4_finger_joint_trans">
        <type>transmission_interface/SimpleTransmission</type>
        <joint name="Link4_finger_joint">
            <hardwareInterface>hardware_interface/EffortJointInterface</hardwareInterface>
        </joint>
        <actuator name="Link4_finger_joint_motor">
            <mechanicalReduction>1</mechanicalReduction>
            <hardwareInterface>hardware_interface/EffortJointInterface</hardwareInterface>
        </actuator>
    </transmission>
    <!-- base link -->
    <link name="Link4_robotiq_arg2f_base_link">
        <inertial>
            <origin rpy="0 0 0" xyz="8.625E-08 -4.6583E-06 0.03145" />
            <mass value="0.22652" />
            <inertia ixx="0.00020005" ixy="-4.2442E-10" ixz="-2.9069E-10" iyy="0.00017832" iyz="-3.4402E-08" izz="0.00013478" />
        </inertial>
        <visual>
            <origin rpy="0 0 0" xyz="0 0 0" />
            <geometry>
                <mesh filename="package://robotiq_2f_85_gripper_visualization/meshes/visual/robotiq_arg2f_base_link.stl" />
            </geometry>
            <material name="">
                <color rgba="0.1 0.1 0.1 1" />
            </material>
        </visual>
        <collision>
            <origin rpy="0 0 0" xyz="0 0 0" />
            <!-- <geometry><sphere radius="0.04" /></geometry> -->
            <geometry>
                <mesh filename="package://robotiq_2f_85_gripper_visualization/meshes/collision/robotiq_arg2f_base_link.stl" />
            </geometry>
            <surface>
                <friction>
                    <torsional>
                        <coefficient>5.0</coefficient>
                        <surface_radius>0.01</surface_radius>
                        <use_patch_radius>false</use_patch_radius>
                    </torsional>
                </friction>
            </surface>
        </collision>
    </link>
    <link name="Link4_left_outer_knuckle">
        <inertial>
            <origin rpy="0 0 0" xyz="-0.000200000000003065 0.0199435877845359 0.0292245259211331" />
            <mass value="0.00853198276973456" />
            <inertia ixx="2.89328108496468E-06" ixy="-1.57935047237397E-19" ixz="-1.93980378593255E-19" iyy="1.86719750325683E-06" iyz="-1.21858577871576E-06" izz="1.21905238907251E-06" />
        </inertial>
        <visual>
            <origin rpy="0 0 0" xyz="0 0 0" />
            <geometry>
                <mesh filename="package://robotiq_2f_85_gripper_visualization/meshes/visual/robotiq_arg2f_85_outer_knuckle.dae" scale="0.001 0.001 0.001" />
            </geometry>
            <material name="">
                <color rgba="0.792156862745098 0.819607843137255 0.933333333333333 1" />
            </material>
        </visual>
        <collision>
            <origin rpy="0 0 0" xyz="0 0 0" />
            <geometry>
                <mesh filename="package://robotiq_2f_85_gripper_visualization/meshes/collision/robotiq_arg2f_85_outer_knuckle.dae" scale="0.001 0.001 0.001" />
            </geometry>
        </collision>
    </link>
    <link name="Link4_left_outer_finger">
        <inertial>
            <origin rpy="0 0 0" xyz="0.00030115855001899 0.0373907951953854 -0.0208027427000385" />
            <mass value="0.022614240507152" />
            <inertia ixx="1.52518312458174E-05" ixy="9.76583423954399E-10" ixz="-5.43838577022588E-10" iyy="6.17694243867776E-06" iyz="6.78636130740228E-06" izz="1.16494917907219E-05" />
        </inertial>
        <visual>
            <origin rpy="0 0 0" xyz="0 0 0" />
            <geometry>
                <mesh filename="package://robotiq_2f_85_gripper_visualization/meshes/visual/robotiq_arg2f_85_outer_finger.dae" scale="0.001 0.001 0.001" />
            </geometry>
            <material name="">
                <color rgba="0.1 0.1 0.1 1" />
            </material>
        </visual>
        <collision>
            <origin rpy="0 0 0" xyz="0 0 0" />
            <geometry>
                <mesh filename="package://robotiq_2f_85_gripper_visualization/meshes/collision/robotiq_arg2f_85_outer_finger.dae" scale="0.001 0.001 0.001" />
            </geometry>
        </collision>
    </link>
    <link name="Link4_left_inner_finger">
        <inertial>
            <origin rpy="0 0 0" xyz="0.000299999999999317 0.0160078233491243 -0.0136945669206257" />
            <mass value="0.0104003125914103" />
            <inertia ixx="2.71909453810972E-06" ixy="1.35402465472579E-21" ixz="-7.1817349065269E-22" iyy="7.69100314106116E-07" iyz="6.74715432769696E-07" izz="2.30315190420171E-06" />
        </inertial>
        <visual>
            <origin rpy="0 0 0" xyz="0 0 0" />
            <geometry>
                <mesh filename="package://robotiq_2f_85_gripper_visualization/meshes/visual/robotiq_arg2f_85_inner_finger.dae" scale="0.001 0.001 0.001" />
            </geometry>
            <material name="">
                <color rgba="0.1 0.1 0.1 1" />
            </material>
        </visual>
        <collision>
            <origin rpy="0 0 0" xyz="0 0 0" />
            <geometry>
                <mesh filename="package://robotiq_2f_85_gripper_visualization/meshes/collision/robotiq_arg2f_85_inner_finger.dae" scale="0.001 0.001 0.001" />
            </geometry>
        </collision>
    </link>
    <link name="Link4_left_inner_finger_pad">
        <visual>
            <origin rpy="0 0 0" xyz="0 0 0" />
            <geometry>
                <box size="0.022 0.00635 0.0375" />
            </geometry>
            <material name="">
                <color rgba="0.9 0.9 0.9 1" />
            </material>
        </visual>
        <collision>
            <origin rpy="0 0 0" xyz="0 0 0" />
            <geometry>
                <box size="0.022 0.00635 0.0375" />
            </geometry>
            <material name="">
                <color rgba="0.9 0.0 0.0 1" />
            </material>
        </collision>
        <inertial>
            <mass value="0.1" />
            <origin xyz="0 0 0" rpy="0 0 0" />
            <inertia ixx="0.03" iyy="0.03" izz="0.03" ixy="0.0" ixz="0.0" iyz="0.0" />
        </inertial>
    </link>
    <link name="Link4_left_inner_knuckle">
        <inertial>
            <origin rpy="0 0 0" xyz="0.000123011831763771 0.0507850843201817 0.00103968640075166" />
            <mass value="0.0271177346495152" />
            <inertia ixx="2.61910379223783E-05" ixy="-2.43616858946494E-07" ixz="-6.37789906117123E-09" iyy="2.8270243746167E-06" iyz="-5.37200748039765E-07" izz="2.83695868220296E-05" />
        </inertial>
        <visual>
            <origin rpy="0 0 0" xyz="0 0 0" />
            <geometry>
                <mesh filename="package://robotiq_2f_85_gripper_visualization/meshes/visual/robotiq_arg2f_85_inner_knuckle.dae" scale="0.001 0.001 0.001" />
            </geometry>
            <material name="">
                <color rgba="0.1 0.1 0.1 1" />
            </material>
        </visual>
        <collision>
            <origin rpy="0 0 0" xyz="0 0 0" />
            <geometry>
                <mesh filename="package://robotiq_2f_85_gripper_visualization/meshes/collision/robotiq_arg2f_85_inner_knuckle.dae" scale="0.001 0.001 0.001" />
            </geometry>
        </collision>
    </link>
    <joint name="Link4_left_outer_finger_joint" type="fixed">
        <origin rpy="0 0 0" xyz="0 0.0315 -0.0041" />
        <parent link="Link4_left_outer_knuckle" />
        <child link="Link4_left_outer_finger" />
        <axis xyz="1 0 0" />
    </joint>
    <joint name="Link4_left_inner_knuckle_joint" type="revolute">
        <!-- <origin xyz="0 ${reflect * -0.0127} 0.06142" rpy="${pi / 2 + .725} 0 ${(reflect - 1) * pi / 2}" /> -->
        <origin rpy="0 0 3.141592653589793" xyz="0 -0.0127 0.06142" />
        <parent link="Link4_robotiq_arg2f_base_link" />
        <child link="Link4_left_inner_knuckle" />
        <axis xyz="1 0 0" />
        <limit effort="1000" lower="0" upper="0.8757" velocity="0.5" />
        <mimic joint="Link4_finger_joint" multiplier="1" offset="0" />
    </joint>
    <joint name="Link4_left_inner_finger_joint" type="revolute">
        <origin rpy="0 0 0" xyz="0 0.0061 0.0471" />
        <parent link="Link4_left_outer_finger" />
        <child link="Link4_left_inner_finger" />
        <axis xyz="1 0 0" />
        <limit effort="1000" lower="-0.8757" upper="0" velocity="0.5" />
        <mimic joint="Link4_finger_joint" multiplier="-1" offset="0" />
    </joint>
    <joint name="Link4_left_inner_finger_pad_joint" type="fixed">
        <origin rpy="0 0 0" xyz="0 -0.0220203446692936 0.03242" />
        <parent link="Link4_left_inner_finger" />
        <child link="Link4_left_inner_finger_pad" />
        <axis xyz="0 0 1" />
    </joint>
    <joint name="Link4_finger_joint" type="revolute">
        <origin rpy="0 0 3.141592653589793" xyz="0 -0.0306011 0.054904" />
        <parent link="Link4_robotiq_arg2f_base_link" />
        <child link="Link4_left_outer_knuckle" />
        <axis xyz="1 0 0" />
        <limit effort="1000" lower="0" upper="0.8" velocity="0.5" />
    </joint>
    <joint name="Link4_right_outer_finger_joint" type="fixed">
        <origin rpy="0 0 0" xyz="0 0.0315 -0.0041" />
        <parent link="Link4_right_outer_knuckle" />
        <child link="Link4_right_outer_finger" />
        <axis xyz="1 0 0" />
    </joint>
    <joint name="Link4_right_inner_knuckle_joint" type="revolute">
        <!-- <origin xyz="0 ${reflect * -0.0127} 0.06142" rpy="${pi / 2 + .725} 0 ${(reflect - 1) * pi / 2}" /> -->
        <origin rpy="0 0 0.0" xyz="0 0.0127 0.06142" />
        <parent link="Link4_robotiq_arg2f_base_link" />
        <child link="Link4_right_inner_knuckle" />
        <axis xyz="1 0 0" />
        <limit effort="1000" lower="0" upper="0.8757" velocity="0.5" />
        <mimic joint="Link4_finger_joint" multiplier="1" offset="0" />
    </joint>
    <joint name="Link4_right_inner_finger_joint" type="revolute">
        <origin rpy="0 0 0" xyz="0 0.0061 0.0471" />
        <parent link="Link4_right_outer_finger" />
        <child link="Link4_right_inner_finger" />
        <axis xyz="1 0 0" />
        <limit effort="1000" lower="-0.8757" upper="0" velocity="0.5" />
        <mimic joint="Link4_finger_joint" multiplier="-1" offset="0" />
    </joint>
    <joint name="Link4_right_inner_finger_pad_joint" type="fixed">
        <origin rpy="0 0 0" xyz="0 -0.0220203446692936 0.03242" />
        <parent link="Link4_right_inner_finger" />
        <child link="Link4_right_inner_finger_pad" />
        <axis xyz="0 0 1" />
    </joint>
    <link name="Link4_right_outer_knuckle">
        <inertial>
            <origin rpy="0 0 0" xyz="-0.000200000000003065 0.0199435877845359 0.0292245259211331" />
            <mass value="0.00853198276973456" />
            <inertia ixx="2.89328108496468E-06" ixy="-1.57935047237397E-19" ixz="-1.93980378593255E-19" iyy="1.86719750325683E-06" iyz="-1.21858577871576E-06" izz="1.21905238907251E-06" />
        </inertial>
        <visual>
            <origin rpy="0 0 0" xyz="0 0 0" />
            <geometry>
                <mesh filename="package://robotiq_2f_85_gripper_visualization/meshes/visual/robotiq_arg2f_85_outer_knuckle.dae" scale="0.001 0.001 0.001" />
            </geometry>
            <material name="">
                <color rgba="0.792156862745098 0.819607843137255 0.933333333333333 1" />
            </material>
        </visual>
        <collision>
            <origin rpy="0 0 0" xyz="0 0 0" />
            <geometry>
                <mesh filename="package://robotiq_2f_85_gripper_visualization/meshes/collision/robotiq_arg2f_85_outer_knuckle.dae" scale="0.001 0.001 0.001" />
            </geometry>
        </collision>
    </link>
    <link name="Link4_right_outer_finger">
        <inertial>
            <origin rpy="0 0 0" xyz="0.00030115855001899 0.0373907951953854 -0.0208027427000385" />
            <mass value="0.022614240507152" />
            <inertia ixx="1.52518312458174E-05" ixy="9.76583423954399E-10" ixz="-5.43838577022588E-10" iyy="6.17694243867776E-06" iyz="6.78636130740228E-06" izz="1.16494917907219E-05" />
        </inertial>
        <visual>
            <origin rpy="0 0 0" xyz="0 0 0" />
            <geometry>
                <mesh filename="package://robotiq_2f_85_gripper_visualization/meshes/visual/robotiq_arg2f_85_outer_finger.dae" scale="0.001 0.001 0.001" />
            </geometry>
            <material name="">
                <color rgba="0.1 0.1 0.1 1" />
            </material>
        </visual>
        <collision>
            <origin rpy="0 0 0" xyz="0 0 0" />
            <geometry>
                <mesh filename="package://robotiq_2f_85_gripper_visualization/meshes/collision/robotiq_arg2f_85_outer_finger.dae" scale="0.001 0.001 0.001" />
            </geometry>
        </collision>
    </link>
    <link name="Link4_right_inner_finger">
        <inertial>
            <origin rpy="0 0 0" xyz="0.000299999999999317 0.0160078233491243 -0.0136945669206257" />
            <mass value="0.0104003125914103" />
            <inertia ixx="2.71909453810972E-06" ixy="1.35402465472579E-21" ixz="-7.1817349065269E-22" iyy="7.69100314106116E-07" iyz="6.74715432769696E-07" izz="2.30315190420171E-06" />
        </inertial>
        <visual>
            <origin rpy="0 0 0" xyz="0 0 0" />
            <geometry>
                <mesh filename="package://robotiq_2f_85_gripper_visualization/meshes/visual/robotiq_arg2f_85_inner_finger.dae" scale="0.001 0.001 0.001" />
            </geometry>
            <material name="">
                <color rgba="0.1 0.1 0.1 1" />
            </material>
        </visual>
        <collision>
            <origin rpy="0 0 0" xyz="0 0 0" />
            <geometry>
                <mesh filename="package://robotiq_2f_85_gripper_visualization/meshes/collision/robotiq_arg2f_85_inner_finger.dae" scale="0.001 0.001 0.001" />
            </geometry>
        </collision>
    </link>
    <link name="Link4_right_inner_finger_pad">
        <visual>
            <origin rpy="0 0 0" xyz="0 0 0" />
            <geometry>
                <box size="0.022 0.00635 0.0375" />
            </geometry>
            <material name="">
                <color rgba="0.9 0.9 0.9 1" />
            </material>
        </visual>
        <collision>
            <origin rpy="0 0 0" xyz="0 0 0" />
            <geometry>
                <box size="0.022 0.00635 0.0375" />
            </geometry>
            <material name="">
                <color rgba="0.9 0.0 0.0 1" />
            </material>
        </collision>
        <inertial>
            <mass value="0.1" />
            <origin xyz="0 0 0" rpy="0 0 0" />
            <inertia ixx="0.03" iyy="0.03" izz="0.03" ixy="0.0" ixz="0.0" iyz="0.0" />
        </inertial>
    </link>
    <link name="Link4_right_inner_knuckle">
        <inertial>
            <origin rpy="0 0 0" xyz="0.000123011831763771 0.0507850843201817 0.00103968640075166" />
            <mass value="0.0271177346495152" />
            <inertia ixx="2.61910379223783E-05" ixy="-2.43616858946494E-07" ixz="-6.37789906117123E-09" iyy="2.8270243746167E-06" iyz="-5.37200748039765E-07" izz="2.83695868220296E-05" />
        </inertial>
        <visual>
            <origin rpy="0 0 0" xyz="0 0 0" />
            <geometry>
                <mesh filename="package://robotiq_2f_85_gripper_visualization/meshes/visual/robotiq_arg2f_85_inner_knuckle.dae" scale="0.001 0.001 0.001" />
            </geometry>
            <material name="">
                <color rgba="0.1 0.1 0.1 1" />
            </material>
        </visual>
        <collision>
            <origin rpy="0 0 0" xyz="0 0 0" />
            <geometry>
                <mesh filename="package://robotiq_2f_85_gripper_visualization/meshes/collision/robotiq_arg2f_85_inner_knuckle.dae" scale="0.001 0.001 0.001" />
            </geometry>
        </collision>
    </link>
    <joint name="Link4_right_finger_joint" type="revolute">
        <origin rpy="0 0 0" xyz="0 0.0306011 0.054904" />
        <parent link="Link4_robotiq_arg2f_base_link" />
        <child link="Link4_right_outer_knuckle" />
        <axis xyz="1 0 0" />
        <limit effort="1000" lower="0" upper="0.81" velocity="0.5" />
        <mimic joint="Link4_finger_joint" multiplier="1" offset="0" />
    </joint>
    <link name="Link1_platlink">
        <inertial>
            <origin rpy="0 0 0" xyz="0.02891563 -0.01184461 0.0004999" />
            <mass value="0.0110" />
            <inertia ixx="2.3755012E-06" ixy="4.9413420E-06" ixz="0" iyy="1.2414435E-05" iyz="0" izz="1.46210848E-05" />
        </inertial>
        <visual>
            <origin rpy="0 0 0" xyz="0 0 0" />
            <geometry>
                <mesh filename="package://robot_description/meshes/Link_platlink.STL" />
            </geometry>
            <material name="">
                <color rgba="1 1 1 1" />
            </material>
        </visual>
        <collision>
            <origin rpy="0 0 0" xyz="0 0 0" />
            <geometry>
                <mesh filename="package://robot_description/meshes/Link_platlink.STL" />
            </geometry>
        </collision>
    </link>
    <joint name="Joint1_platlink" type="revolute">
        <origin rpy="1.5707963267948966 0 0.7853981633974483" xyz="0.056569 0.056569 0" />
        <parent link="Link_platform" />
        <child link="Link1_platlink" />
        <axis xyz="0 0 1" />
        <dynamics damping="0.1" friction="0.8" />
        <limit effort="1000" lower="-1.5707963267948966" upper="0" velocity="10" />
    </joint>
    <link name="Link2_platlink">
        <inertial>
            <origin rpy="0 0 0" xyz="0.02891563 -0.01184461 0.0004999" />
            <mass value="0.0110" />
            <inertia ixx="2.3755012E-06" ixy="4.9413420E-06" ixz="0" iyy="1.2414435E-05" iyz="0" izz="1.46210848E-05" />
        </inertial>
        <visual>
            <origin rpy="0 0 0" xyz="0 0 0" />
            <geometry>
                <mesh filename="package://robot_description/meshes/Link_platlink.STL" />
            </geometry>
            <material name="">
                <color rgba="1 1 1 1" />
            </material>
        </visual>
        <collision>
            <origin rpy="0 0 0" xyz="0 0 0" />
            <geometry>
                <mesh filename="package://robot_description/meshes/Link_platlink.STL" />
            </geometry>
        </collision>
    </link>
    <joint name="Joint2_platlink" type="revolute">
        <origin rpy="1.5707963267948966 0 2.356194490192345" xyz="-0.056569 0.056569 0" />
        <parent link="Link_platform" />
        <child link="Link2_platlink" />
        <axis xyz="0 0 1" />
        <dynamics damping="0.1" friction="0.8" />
        <limit effort="1000" lower="-1.5707963267948966" upper="0" velocity="10" />
    </joint>
    <link name="Link3_platlink">
        <inertial>
            <origin rpy="0 0 0" xyz="0.02891563 -0.01184461 0.0004999" />
            <mass value="0.0110" />
            <inertia ixx="2.3755012E-06" ixy="4.9413420E-06" ixz="0" iyy="1.2414435E-05" iyz="0" izz="1.46210848E-05" />
        </inertial>
        <visual>
            <origin rpy="0 0 0" xyz="0 0 0" />
            <geometry>
                <mesh filename="package://robot_description/meshes/Link_platlink.STL" />
            </geometry>
            <material name="">
                <color rgba="1 1 1 1" />
            </material>
        </visual>
        <collision>
            <origin rpy="0 0 0" xyz="0 0 0" />
            <geometry>
                <mesh filename="package://robot_description/meshes/Link_platlink.STL" />
            </geometry>
        </collision>
    </link>
    <joint name="Joint3_platlink" type="revolute">
        <origin rpy="1.5707963267948966 0 3.9269908169872414" xyz="-0.056569 -0.056569 0" />
        <parent link="Link_platform" />
        <child link="Link3_platlink" />
        <axis xyz="0 0 1" />
        <dynamics damping="0.1" friction="0.8" />
        <limit effort="1000" lower="-1.5707963267948966" upper="0" velocity="10" />
    </joint>
    <link name="Link4_platlink">
        <inertial>
            <origin rpy="0 0 0" xyz="0.02891563 -0.01184461 0.0004999" />
            <mass value="0.0110" />
            <inertia ixx="2.3755012E-06" ixy="4.9413420E-06" ixz="0" iyy="1.2414435E-05" iyz="0" izz="1.46210848E-05" />
        </inertial>
        <visual>
            <origin rpy="0 0 0" xyz="0 0 0" />
            <geometry>
                <mesh filename="package://robot_description/meshes/Link_platlink.STL" />
            </geometry>
            <material name="">
                <color rgba="1 1 1 1" />
            </material>
        </visual>
        <collision>
            <origin rpy="0 0 0" xyz="0 0 0" />
            <geometry>
                <mesh filename="package://robot_description/meshes/Link_platlink.STL" />
            </geometry>
        </collision>
    </link>
    <joint name="Joint4_platlink" type="revolute">
        <origin rpy="1.5707963267948966 0 5.497787143782138" xyz="0.056569 -0.056569 0" />
        <parent link="Link_platform" />
        <child link="Link4_platlink" />
        <axis xyz="0 0 1" />
        <dynamics damping="0.1" friction="0.8" />
        <limit effort="1000" lower="-1.5707963267948966" upper="0" velocity="10" />
    </joint>
    <transmission name="trans_Joint_platform">
        <type>transmission_interface/SimpleTransmission</type>
        <joint name="Joint_platform">
            <hardwareInterface>hardware_interface/EffortJointInterface</hardwareInterface>
        </joint>
        <actuator name="Joint_platform_motor">
            <hardwareInterface>hardware_interface/EffortJointInterface</hardwareInterface>
            <mechanicalReduction>1</mechanicalReduction>
        </actuator>
    </transmission>
    <transmission name="trans_Joint1_0">
        <type>transmission_interface/SimpleTransmission</type>
        <joint name="Joint1_0">
            <hardwareInterface>hardware_interface/EffortJointInterface</hardwareInterface>
        </joint>
        <actuator name="Joint1_0_motor">
            <hardwareInterface>hardware_interface/EffortJointInterface</hardwareInterface>
            <mechanicalReduction>1</mechanicalReduction>
        </actuator>
    </transmission>
    <transmission name="trans_Joint1_1">
        <type>transmission_interface/SimpleTransmission</type>
        <joint name="Joint1_1">
            <hardwareInterface>hardware_interface/EffortJointInterface</hardwareInterface>
        </joint>
        <actuator name="Joint1_1_motor">
            <hardwareInterface>hardware_interface/EffortJointInterface</hardwareInterface>
            <mechanicalReduction>1</mechanicalReduction>
        </actuator>
    </transmission>
    <transmission name="trans_Joint1_2">
        <type>transmission_interface/SimpleTransmission</type>
        <joint name="Joint1_2">
            <hardwareInterface>hardware_interface/EffortJointInterface</hardwareInterface>
        </joint>
        <actuator name="Joint1_2_motor">
            <hardwareInterface>hardware_interface/EffortJointInterface</hardwareInterface>
            <mechanicalReduction>1</mechanicalReduction>
        </actuator>
    </transmission>
    <transmission name="trans_Joint1_3">
        <type>transmission_interface/SimpleTransmission</type>
        <joint name="Joint1_3">
            <hardwareInterface>hardware_interface/EffortJointInterface</hardwareInterface>
        </joint>
        <actuator name="Joint1_3_motor">
            <hardwareInterface>hardware_interface/EffortJointInterface</hardwareInterface>
            <mechanicalReduction>1</mechanicalReduction>
        </actuator>
    </transmission>
    <transmission name="trans_Joint1_4">
        <type>transmission_interface/SimpleTransmission</type>
        <joint name="Joint1_4">
            <hardwareInterface>hardware_interface/EffortJointInterface</hardwareInterface>
        </joint>
        <actuator name="Joint1_4_motor">
            <hardwareInterface>hardware_interface/EffortJointInterface</hardwareInterface>
            <mechanicalReduction>1</mechanicalReduction>
        </actuator>
    </transmission>
    <transmission name="trans_Joint1_5">
        <type>transmission_interface/SimpleTransmission</type>
        <joint name="Joint1_5">
            <hardwareInterface>hardware_interface/EffortJointInterface</hardwareInterface>
        </joint>
        <actuator name="Joint1_5_motor">
            <hardwareInterface>hardware_interface/EffortJointInterface</hardwareInterface>
            <mechanicalReduction>1</mechanicalReduction>
        </actuator>
    </transmission>
    <transmission name="trans_Joint1_6">
        <type>transmission_interface/SimpleTransmission</type>
        <joint name="Joint1_6">
            <hardwareInterface>hardware_interface/EffortJointInterface</hardwareInterface>
        </joint>
        <actuator name="Joint1_6_motor">
            <hardwareInterface>hardware_interface/EffortJointInterface</hardwareInterface>
            <mechanicalReduction>1</mechanicalReduction>
        </actuator>
    </transmission>
    <transmission name="trans_Link1_left_inner_knuckle_joint">
        <type>transmission_interface/SimpleTransmission</type>
        <joint name="Link1_left_inner_knuckle_joint">
            <hardwareInterface>hardware_interface/EffortJointInterface</hardwareInterface>
        </joint>
        <actuator name="Link1_left_inner_knuckle_joint_motor">
            <hardwareInterface>hardware_interface/EffortJointInterface</hardwareInterface>
            <mechanicalReduction>1</mechanicalReduction>
        </actuator>
    </transmission>
    <transmission name="trans_Link1_left_inner_finger_joint">
        <type>transmission_interface/SimpleTransmission</type>
        <joint name="Link1_left_inner_finger_joint">
            <hardwareInterface>hardware_interface/EffortJointInterface</hardwareInterface>
        </joint>
        <actuator name="Link1_left_inner_finger_joint_motor">
            <hardwareInterface>hardware_interface/EffortJointInterface</hardwareInterface>
            <mechanicalReduction>1</mechanicalReduction>
        </actuator>
    </transmission>
    <transmission name="trans_Link1_right_inner_knuckle_joint">
        <type>transmission_interface/SimpleTransmission</type>
        <joint name="Link1_right_inner_knuckle_joint">
            <hardwareInterface>hardware_interface/EffortJointInterface</hardwareInterface>
        </joint>
        <actuator name="Link1_right_inner_knuckle_joint_motor">
            <hardwareInterface>hardware_interface/EffortJointInterface</hardwareInterface>
            <mechanicalReduction>1</mechanicalReduction>
        </actuator>
    </transmission>
    <transmission name="trans_Link1_right_inner_finger_joint">
        <type>transmission_interface/SimpleTransmission</type>
        <joint name="Link1_right_inner_finger_joint">
            <hardwareInterface>hardware_interface/EffortJointInterface</hardwareInterface>
        </joint>
        <actuator name="Link1_right_inner_finger_joint_motor">
            <hardwareInterface>hardware_interface/EffortJointInterface</hardwareInterface>
            <mechanicalReduction>1</mechanicalReduction>
        </actuator>
    </transmission>
    <transmission name="trans_Link1_right_finger_joint">
        <type>transmission_interface/SimpleTransmission</type>
        <joint name="Link1_right_finger_joint">
            <hardwareInterface>hardware_interface/EffortJointInterface</hardwareInterface>
        </joint>
        <actuator name="Link1_right_finger_joint_motor">
            <hardwareInterface>hardware_interface/EffortJointInterface</hardwareInterface>
            <mechanicalReduction>1</mechanicalReduction>
        </actuator>
    </transmission>
    <transmission name="trans_Joint2_0">
        <type>transmission_interface/SimpleTransmission</type>
        <joint name="Joint2_0">
            <hardwareInterface>hardware_interface/EffortJointInterface</hardwareInterface>
        </joint>
        <actuator name="Joint2_0_motor">
            <hardwareInterface>hardware_interface/EffortJointInterface</hardwareInterface>
            <mechanicalReduction>1</mechanicalReduction>
        </actuator>
    </transmission>
    <transmission name="trans_Joint2_1">
        <type>transmission_interface/SimpleTransmission</type>
        <joint name="Joint2_1">
            <hardwareInterface>hardware_interface/EffortJointInterface</hardwareInterface>
        </joint>
        <actuator name="Joint2_1_motor">
            <hardwareInterface>hardware_interface/EffortJointInterface</hardwareInterface>
            <mechanicalReduction>1</mechanicalReduction>
        </actuator>
    </transmission>
    <transmission name="trans_Joint2_2">
        <type>transmission_interface/SimpleTransmission</type>
        <joint name="Joint2_2">
            <hardwareInterface>hardware_interface/EffortJointInterface</hardwareInterface>
        </joint>
        <actuator name="Joint2_2_motor">
            <hardwareInterface>hardware_interface/EffortJointInterface</hardwareInterface>
            <mechanicalReduction>1</mechanicalReduction>
        </actuator>
    </transmission>
    <transmission name="trans_Joint2_3">
        <type>transmission_interface/SimpleTransmission</type>
        <joint name="Joint2_3">
            <hardwareInterface>hardware_interface/EffortJointInterface</hardwareInterface>
        </joint>
        <actuator name="Joint2_3_motor">
            <hardwareInterface>hardware_interface/EffortJointInterface</hardwareInterface>
            <mechanicalReduction>1</mechanicalReduction>
        </actuator>
    </transmission>
    <transmission name="trans_Joint2_4">
        <type>transmission_interface/SimpleTransmission</type>
        <joint name="Joint2_4">
            <hardwareInterface>hardware_interface/EffortJointInterface</hardwareInterface>
        </joint>
        <actuator name="Joint2_4_motor">
            <hardwareInterface>hardware_interface/EffortJointInterface</hardwareInterface>
            <mechanicalReduction>1</mechanicalReduction>
        </actuator>
    </transmission>
    <transmission name="trans_Joint2_5">
        <type>transmission_interface/SimpleTransmission</type>
        <joint name="Joint2_5">
            <hardwareInterface>hardware_interface/EffortJointInterface</hardwareInterface>
        </joint>
        <actuator name="Joint2_5_motor">
            <hardwareInterface>hardware_interface/EffortJointInterface</hardwareInterface>
            <mechanicalReduction>1</mechanicalReduction>
        </actuator>
    </transmission>
    <transmission name="trans_Joint2_6">
        <type>transmission_interface/SimpleTransmission</type>
        <joint name="Joint2_6">
            <hardwareInterface>hardware_interface/EffortJointInterface</hardwareInterface>
        </joint>
        <actuator name="Joint2_6_motor">
            <hardwareInterface>hardware_interface/EffortJointInterface</hardwareInterface>
            <mechanicalReduction>1</mechanicalReduction>
        </actuator>
    </transmission>
    <transmission name="trans_Link2_left_inner_knuckle_joint">
        <type>transmission_interface/SimpleTransmission</type>
        <joint name="Link2_left_inner_knuckle_joint">
            <hardwareInterface>hardware_interface/EffortJointInterface</hardwareInterface>
        </joint>
        <actuator name="Link2_left_inner_knuckle_joint_motor">
            <hardwareInterface>hardware_interface/EffortJointInterface</hardwareInterface>
            <mechanicalReduction>1</mechanicalReduction>
        </actuator>
    </transmission>
    <transmission name="trans_Link2_left_inner_finger_joint">
        <type>transmission_interface/SimpleTransmission</type>
        <joint name="Link2_left_inner_finger_joint">
            <hardwareInterface>hardware_interface/EffortJointInterface</hardwareInterface>
        </joint>
        <actuator name="Link2_left_inner_finger_joint_motor">
            <hardwareInterface>hardware_interface/EffortJointInterface</hardwareInterface>
            <mechanicalReduction>1</mechanicalReduction>
        </actuator>
    </transmission>
    <transmission name="trans_Link2_right_inner_knuckle_joint">
        <type>transmission_interface/SimpleTransmission</type>
        <joint name="Link2_right_inner_knuckle_joint">
            <hardwareInterface>hardware_interface/EffortJointInterface</hardwareInterface>
        </joint>
        <actuator name="Link2_right_inner_knuckle_joint_motor">
            <hardwareInterface>hardware_interface/EffortJointInterface</hardwareInterface>
            <mechanicalReduction>1</mechanicalReduction>
        </actuator>
    </transmission>
    <transmission name="trans_Link2_right_inner_finger_joint">
        <type>transmission_interface/SimpleTransmission</type>
        <joint name="Link2_right_inner_finger_joint">
            <hardwareInterface>hardware_interface/EffortJointInterface</hardwareInterface>
        </joint>
        <actuator name="Link2_right_inner_finger_joint_motor">
            <hardwareInterface>hardware_interface/EffortJointInterface</hardwareInterface>
            <mechanicalReduction>1</mechanicalReduction>
        </actuator>
    </transmission>
    <transmission name="trans_Link2_right_finger_joint">
        <type>transmission_interface/SimpleTransmission</type>
        <joint name="Link2_right_finger_joint">
            <hardwareInterface>hardware_interface/EffortJointInterface</hardwareInterface>
        </joint>
        <actuator name="Link2_right_finger_joint_motor">
            <hardwareInterface>hardware_interface/EffortJointInterface</hardwareInterface>
            <mechanicalReduction>1</mechanicalReduction>
        </actuator>
    </transmission>
    <transmission name="trans_Joint3_0">
        <type>transmission_interface/SimpleTransmission</type>
        <joint name="Joint3_0">
            <hardwareInterface>hardware_interface/EffortJointInterface</hardwareInterface>
        </joint>
        <actuator name="Joint3_0_motor">
            <hardwareInterface>hardware_interface/EffortJointInterface</hardwareInterface>
            <mechanicalReduction>1</mechanicalReduction>
        </actuator>
    </transmission>
    <transmission name="trans_Joint3_1">
        <type>transmission_interface/SimpleTransmission</type>
        <joint name="Joint3_1">
            <hardwareInterface>hardware_interface/EffortJointInterface</hardwareInterface>
        </joint>
        <actuator name="Joint3_1_motor">
            <hardwareInterface>hardware_interface/EffortJointInterface</hardwareInterface>
            <mechanicalReduction>1</mechanicalReduction>
        </actuator>
    </transmission>
    <transmission name="trans_Joint3_2">
        <type>transmission_interface/SimpleTransmission</type>
        <joint name="Joint3_2">
            <hardwareInterface>hardware_interface/EffortJointInterface</hardwareInterface>
        </joint>
        <actuator name="Joint3_2_motor">
            <hardwareInterface>hardware_interface/EffortJointInterface</hardwareInterface>
            <mechanicalReduction>1</mechanicalReduction>
        </actuator>
    </transmission>
    <transmission name="trans_Joint3_3">
        <type>transmission_interface/SimpleTransmission</type>
        <joint name="Joint3_3">
            <hardwareInterface>hardware_interface/EffortJointInterface</hardwareInterface>
        </joint>
        <actuator name="Joint3_3_motor">
            <hardwareInterface>hardware_interface/EffortJointInterface</hardwareInterface>
            <mechanicalReduction>1</mechanicalReduction>
        </actuator>
    </transmission>
    <transmission name="trans_Joint3_4">
        <type>transmission_interface/SimpleTransmission</type>
        <joint name="Joint3_4">
            <hardwareInterface>hardware_interface/EffortJointInterface</hardwareInterface>
        </joint>
        <actuator name="Joint3_4_motor">
            <hardwareInterface>hardware_interface/EffortJointInterface</hardwareInterface>
            <mechanicalReduction>1</mechanicalReduction>
        </actuator>
    </transmission>
    <transmission name="trans_Joint3_5">
        <type>transmission_interface/SimpleTransmission</type>
        <joint name="Joint3_5">
            <hardwareInterface>hardware_interface/EffortJointInterface</hardwareInterface>
        </joint>
        <actuator name="Joint3_5_motor">
            <hardwareInterface>hardware_interface/EffortJointInterface</hardwareInterface>
            <mechanicalReduction>1</mechanicalReduction>
        </actuator>
    </transmission>
    <transmission name="trans_Joint3_6">
        <type>transmission_interface/SimpleTransmission</type>
        <joint name="Joint3_6">
            <hardwareInterface>hardware_interface/EffortJointInterface</hardwareInterface>
        </joint>
        <actuator name="Joint3_6_motor">
            <hardwareInterface>hardware_interface/EffortJointInterface</hardwareInterface>
            <mechanicalReduction>1</mechanicalReduction>
        </actuator>
    </transmission>
    <transmission name="trans_Link3_left_inner_knuckle_joint">
        <type>transmission_interface/SimpleTransmission</type>
        <joint name="Link3_left_inner_knuckle_joint">
            <hardwareInterface>hardware_interface/EffortJointInterface</hardwareInterface>
        </joint>
        <actuator name="Link3_left_inner_knuckle_joint_motor">
            <hardwareInterface>hardware_interface/EffortJointInterface</hardwareInterface>
            <mechanicalReduction>1</mechanicalReduction>
        </actuator>
    </transmission>
    <transmission name="trans_Link3_left_inner_finger_joint">
        <type>transmission_interface/SimpleTransmission</type>
        <joint name="Link3_left_inner_finger_joint">
            <hardwareInterface>hardware_interface/EffortJointInterface</hardwareInterface>
        </joint>
        <actuator name="Link3_left_inner_finger_joint_motor">
            <hardwareInterface>hardware_interface/EffortJointInterface</hardwareInterface>
            <mechanicalReduction>1</mechanicalReduction>
        </actuator>
    </transmission>
    <transmission name="trans_Link3_right_inner_knuckle_joint">
        <type>transmission_interface/SimpleTransmission</type>
        <joint name="Link3_right_inner_knuckle_joint">
            <hardwareInterface>hardware_interface/EffortJointInterface</hardwareInterface>
        </joint>
        <actuator name="Link3_right_inner_knuckle_joint_motor">
            <hardwareInterface>hardware_interface/EffortJointInterface</hardwareInterface>
            <mechanicalReduction>1</mechanicalReduction>
        </actuator>
    </transmission>
    <transmission name="trans_Link3_right_inner_finger_joint">
        <type>transmission_interface/SimpleTransmission</type>
        <joint name="Link3_right_inner_finger_joint">
            <hardwareInterface>hardware_interface/EffortJointInterface</hardwareInterface>
        </joint>
        <actuator name="Link3_right_inner_finger_joint_motor">
            <hardwareInterface>hardware_interface/EffortJointInterface</hardwareInterface>
            <mechanicalReduction>1</mechanicalReduction>
        </actuator>
    </transmission>
    <transmission name="trans_Link3_right_finger_joint">
        <type>transmission_interface/SimpleTransmission</type>
        <joint name="Link3_right_finger_joint">
            <hardwareInterface>hardware_interface/EffortJointInterface</hardwareInterface>
        </joint>
        <actuator name="Link3_right_finger_joint_motor">
            <hardwareInterface>hardware_interface/EffortJointInterface</hardwareInterface>
            <mechanicalReduction>1</mechanicalReduction>
        </actuator>
    </transmission>
    <transmission name="trans_Joint4_0">
        <type>transmission_interface/SimpleTransmission</type>
        <joint name="Joint4_0">
            <hardwareInterface>hardware_interface/EffortJointInterface</hardwareInterface>
        </joint>
        <actuator name="Joint4_0_motor">
            <hardwareInterface>hardware_interface/EffortJointInterface</hardwareInterface>
            <mechanicalReduction>1</mechanicalReduction>
        </actuator>
    </transmission>
    <transmission name="trans_Joint4_1">
        <type>transmission_interface/SimpleTransmission</type>
        <joint name="Joint4_1">
            <hardwareInterface>hardware_interface/EffortJointInterface</hardwareInterface>
        </joint>
        <actuator name="Joint4_1_motor">
            <hardwareInterface>hardware_interface/EffortJointInterface</hardwareInterface>
            <mechanicalReduction>1</mechanicalReduction>
        </actuator>
    </transmission>
    <transmission name="trans_Joint4_2">
        <type>transmission_interface/SimpleTransmission</type>
        <joint name="Joint4_2">
            <hardwareInterface>hardware_interface/EffortJointInterface</hardwareInterface>
        </joint>
        <actuator name="Joint4_2_motor">
            <hardwareInterface>hardware_interface/EffortJointInterface</hardwareInterface>
            <mechanicalReduction>1</mechanicalReduction>
        </actuator>
    </transmission>
    <transmission name="trans_Joint4_3">
        <type>transmission_interface/SimpleTransmission</type>
        <joint name="Joint4_3">
            <hardwareInterface>hardware_interface/EffortJointInterface</hardwareInterface>
        </joint>
        <actuator name="Joint4_3_motor">
            <hardwareInterface>hardware_interface/EffortJointInterface</hardwareInterface>
            <mechanicalReduction>1</mechanicalReduction>
        </actuator>
    </transmission>
    <transmission name="trans_Joint4_4">
        <type>transmission_interface/SimpleTransmission</type>
        <joint name="Joint4_4">
            <hardwareInterface>hardware_interface/EffortJointInterface</hardwareInterface>
        </joint>
        <actuator name="Joint4_4_motor">
            <hardwareInterface>hardware_interface/EffortJointInterface</hardwareInterface>
            <mechanicalReduction>1</mechanicalReduction>
        </actuator>
    </transmission>
    <transmission name="trans_Joint4_5">
        <type>transmission_interface/SimpleTransmission</type>
        <joint name="Joint4_5">
            <hardwareInterface>hardware_interface/EffortJointInterface</hardwareInterface>
        </joint>
        <actuator name="Joint4_5_motor">
            <hardwareInterface>hardware_interface/EffortJointInterface</hardwareInterface>
            <mechanicalReduction>1</mechanicalReduction>
        </actuator>
    </transmission>
    <transmission name="trans_Joint4_6">
        <type>transmission_interface/SimpleTransmission</type>
        <joint name="Joint4_6">
            <hardwareInterface>hardware_interface/EffortJointInterface</hardwareInterface>
        </joint>
        <actuator name="Joint4_6_motor">
            <hardwareInterface>hardware_interface/EffortJointInterface</hardwareInterface>
            <mechanicalReduction>1</mechanicalReduction>
        </actuator>
    </transmission>
    <transmission name="trans_Link4_left_inner_knuckle_joint">
        <type>transmission_interface/SimpleTransmission</type>
        <joint name="Link4_left_inner_knuckle_joint">
            <hardwareInterface>hardware_interface/EffortJointInterface</hardwareInterface>
        </joint>
        <actuator name="Link4_left_inner_knuckle_joint_motor">
            <hardwareInterface>hardware_interface/EffortJointInterface</hardwareInterface>
            <mechanicalReduction>1</mechanicalReduction>
        </actuator>
    </transmission>
    <transmission name="trans_Link4_left_inner_finger_joint">
        <type>transmission_interface/SimpleTransmission</type>
        <joint name="Link4_left_inner_finger_joint">
            <hardwareInterface>hardware_interface/EffortJointInterface</hardwareInterface>
        </joint>
        <actuator name="Link4_left_inner_finger_joint_motor">
            <hardwareInterface>hardware_interface/EffortJointInterface</hardwareInterface>
            <mechanicalReduction>1</mechanicalReduction>
        </actuator>
    </transmission>
    <transmission name="trans_Link4_right_inner_knuckle_joint">
        <type>transmission_interface/SimpleTransmission</type>
        <joint name="Link4_right_inner_knuckle_joint">
            <hardwareInterface>hardware_interface/EffortJointInterface</hardwareInterface>
        </joint>
        <actuator name="Link4_right_inner_knuckle_joint_motor">
            <hardwareInterface>hardware_interface/EffortJointInterface</hardwareInterface>
            <mechanicalReduction>1</mechanicalReduction>
        </actuator>
    </transmission>
    <transmission name="trans_Link4_right_inner_finger_joint">
        <type>transmission_interface/SimpleTransmission</type>
        <joint name="Link4_right_inner_finger_joint">
            <hardwareInterface>hardware_interface/EffortJointInterface</hardwareInterface>
        </joint>
        <actuator name="Link4_right_inner_finger_joint_motor">
            <hardwareInterface>hardware_interface/EffortJointInterface</hardwareInterface>
            <mechanicalReduction>1</mechanicalReduction>
        </actuator>
    </transmission>
    <transmission name="trans_Link4_right_finger_joint">
        <type>transmission_interface/SimpleTransmission</type>
        <joint name="Link4_right_finger_joint">
            <hardwareInterface>hardware_interface/EffortJointInterface</hardwareInterface>
        </joint>
        <actuator name="Link4_right_finger_joint_motor">
            <hardwareInterface>hardware_interface/EffortJointInterface</hardwareInterface>
            <mechanicalReduction>1</mechanicalReduction>
        </actuator>
    </transmission>
    <transmission name="trans_Joint1_platlink">
        <type>transmission_interface/SimpleTransmission</type>
        <joint name="Joint1_platlink">
            <hardwareInterface>hardware_interface/EffortJointInterface</hardwareInterface>
        </joint>
        <actuator name="Joint1_platlink_motor">
            <hardwareInterface>hardware_interface/EffortJointInterface</hardwareInterface>
            <mechanicalReduction>1</mechanicalReduction>
        </actuator>
    </transmission>
    <transmission name="trans_Joint2_platlink">
        <type>transmission_interface/SimpleTransmission</type>
        <joint name="Joint2_platlink">
            <hardwareInterface>hardware_interface/EffortJointInterface</hardwareInterface>
        </joint>
        <actuator name="Joint2_platlink_motor">
            <hardwareInterface>hardware_interface/EffortJointInterface</hardwareInterface>
            <mechanicalReduction>1</mechanicalReduction>
        </actuator>
    </transmission>
    <transmission name="trans_Joint3_platlink">
        <type>transmission_interface/SimpleTransmission</type>
        <joint name="Joint3_platlink">
            <hardwareInterface>hardware_interface/EffortJointInterface</hardwareInterface>
        </joint>
        <actuator name="Joint3_platlink_motor">
            <hardwareInterface>hardware_interface/EffortJointInterface</hardwareInterface>
            <mechanicalReduction>1</mechanicalReduction>
        </actuator>
    </transmission>
    <transmission name="trans_Joint4_platlink">
        <type>transmission_interface/SimpleTransmission</type>
        <joint name="Joint4_platlink">
            <hardwareInterface>hardware_interface/EffortJointInterface</hardwareInterface>
        </joint>
        <actuator name="Joint4_platlink_motor">
            <hardwareInterface>hardware_interface/EffortJointInterface</hardwareInterface>
            <mechanicalReduction>1</mechanicalReduction>
        </actuator>
    </transmission>
    <gazebo>
        <plugin name="gazebo_ros_control" filename="libgazebo_ros_control.so">
            <robotNamespace>/</robotNamespace>
        </plugin>
    </gazebo>
</robot>

